Workbook

Sheet Overview
A1: Sheet | B1: Use | C1: Input
A2: Export | B2: Consolidate dataset with all the information used for the environmental proxy including: vessel's IMO, DWT, Type, Age, Emissions Proxy and Flag. | C2: AXS and GreenVoyage 2050
A3: Emissions proxy | B3: Individual calculation of Environmental Proxy. | C3: AXS and GreenVoyage 2050
A4: Mapping | B4: Mapping between vessel type and size. Consolidation of AXS and GreenVoyage naming of vessel's type. | C4: AXS and GreenVoyage 2050
A5: Age | B5: Constructed after retrieving the built year of all vessels since it was not available directly in only one AXS dataset. | C5: AXS
A6: Shadow Fleet | B6: Specific dataset signalling shadow vessels. Used to build the binary in the final dataset. | C6: AXS

Sheet Export
A1: Date | B1: Move | C1: IMO | D1: Name | E1: Shadow | F1: Shadow Status | G1: Dwt | H1: Segment | I1: Vessel flag | J1: ais destination | K1: Proxy of total annual CO2 emissions (based on size type and fuel consumption) | L1: Build year | M1: Proxy considering built year
A2: 46069 | B2: East→West | C2: 9221267 | D2: OCEANA KAI | E2: 1 | F2: SANCTIONED FLEET | G2: 14804 | H2: chemoil | I2: ABW | J2: Khor Fakkan | K2: 12170.969 | L2: 2001 | M2: 13692.34
A3: 46076 | B3: West→East | C3: 9155626 | D3: ROYAL A | E3: 0 | F3: 0 | G3: 18094 | H3: lpg | I3: ABW | J3: Shinas | K3: 12170.969 | L3: 1998 | M3: 13874.905
A4: 46080 | B4: East→West | C4: 9007386 | D4: XI WANG MU | E4: 0 | F4: 0 | G4: 50357 | H4: lpg | I4: ABW | J4: Hamriya Free Zone Port | K4: 20866.017 | L4: 1991 | M4: 23995.92
A5: 46098 | B5: East→West | C5: 9125724 | D5: BLOOMING DALE | E5: 1 | F5: SANCTIONED FLEET | G5: 12083 | H5: tanker | I5: ABW | J5: Khor Fakkan | K5: 11412.358 | L5: 1996 | M5: 13124.212
A6: 46094 | B6: West→East | C6: 9125724 | D6: BLOOMING DALE | E6: 1 | F6: SANCTIONED FLEET | G6: 12083 | H6: tanker | I6: ABW | J6: Khor Fakkan | K6: 11412.358 | L6: 1996 | M6: 13124.212
A7: 46073 | B7: West→East | C7: 9176656 | D7: ASTRID 1 | E7: 1 | F7: SANCTIONED FLEET | G7: 32950 | H7: tanker | I7: ABW | J7: Khor Fakkan | K7: 19496.252 | L7: 1999 | M7: 22128.246
A8: 46098 | B8: West→East | C8: 9277761 | D8: STELLANN | E8: 1 | F8: GHOST FLEET | G8: 74999 | H8: tanker | I8: ABW | J8: Lianyungang | K8: 26090.7 | L8: 2004 | M8: 28960.677
A9: 46092 | B9: West→East | C9: 9031519 | D9: MARSER | E9: 0 | F9: 0 | G9: 49242 | H9: lpg | I9: AGO | J9: For Orders | K9: 20866.017 | L9: 1993 | M9: 23995.92
A10: 46080 | B10: East→West | C10: 9031519 | D10: MARSER | E10: 0 | F10: 0 | G10: 49242 | H10: lpg | I10: AGO | J10: Khasab | K10: 20866.017 | L10: 1993 | M10: 23995.92
A11: 46097 | B11: East→West | C11: 9115303 | D11: NAVIXON | E11: 0 | F11: 0 | G11: 49849 | H11: lpg | I11: AGO | J11: For Orders | K11: 20866.017 | L11: 1996 | M11: 23995.92
A12: 46096 | B12: West→East | C12: 9115303 | D12: NAVIXON | E12: 0 | F12: 0 | G12: 49849 | H12: lpg | I12: AGO | J12: For Orders | K12: 20866.017 | L12: 1996 | M12: 23995.92
A13: 46088 | B13: East→West | C13: 9115303 | D13: NAVIXON | E13: 0 | F13: 0 | G13: 49849 | H13: lpg | I13: AGO | J13: For Orders | K13: 20866.017 | L13: 1996 | M13: 23995.92
A14: 46073 | B14: West→East | C14: 9005053 | D14: AXON I | E14: 0 | F14: 0 | G14: 49874 | H14: lpg | I14: AGO | J14: Zhuhai | K14: 20866.017 | L14: 1993 | M14: 23995.92
A15: 46078 | B15: East→West | C15: 9592898 | D15: GHANTOUT | E15: 0 | F15: 0 | G15: 23186 | H15: dry | I15: ARE | J15: Port Rashid | K15: 10987.028 | L15: 2011 | M15: 11811.055
A16: 46098 | B16: East→West | C16: 9574016 | D16: AL SADR - I | E16: 0 | F16: 0 | G16: 13944 | H16: liner | I16: ARE | J16: World Wide | K16: 14853.494 | L16: 2011 | M16: 15967.506
A17: 46096 | B17: West→East | C17: 9574016 | D17: AL SADR - I | E17: 0 | F17: 0 | G17: 13944 | H17: liner | I17: ARE | J17: World Wide | K17: 14853.494 | L17: 2011 | M17: 15967.506
A18: 46075 | B18: East→West | C18: 9424534 | D18: FNSA 11 | E18: 0 | F18: 0 | G18: 6472 | H18: tanker | I18: ARE | J18: Port Rashid | K18: 7155.0784 | L18: 2007 | M18: 7834.8109
A19: 46076 | B19: East→West | C19: 9351816 | D19: BHAGYA LAXMI | E19: 0 | F19: 0 | G19: 13433 | H19: liner | I19: ATG | J19: Jebel Ali | K19: 14853.494 | L19: 2008 | M19: 16190.308
A20: 46079 | B20: West→East | C20: 9423035 | D20: NORDIA | E20: 0 | F20: 0 | G20: 42454 | H20: liner | I20: ATG | J20: Dar es Salaam | K20: 14853.494 | L20: 2010 | M20: 16041.773
... A32: 46071 | B32: West→East | C32: 9436329 | D32: BBC VOLGA | E32: 0 | F32: 0 | G32: 17303 | H32: mpp | I32: ATG | J32: Fujairah | K32: 14853.494 | L32: 2009 | M32: 16116.041
A33: 46080 | B33: East→West | C33: 9467158 | D33: OPAL | E33: 0 | F33: SANCTIONED FLEET | G33: 19324 | H33: mpp | I33: ATG | J33: Khasab | K33: 14853.494 | L33: 2012 | M33: 15893.238
A34: 46075 | B34: West→East | C34: 9605906 | D34: BBC ICELAND | E34: 0 | F34: 0 | G34: 24935 | H34: mpp | I34: ATG | J34: Fujairah | K34: 14853.494 | L34: 2013 | M34: 15818.971
A35: 46080 | B35: East→West | C35: 9450208 | D35: ATLAS | E35: 0 | F35: 0 | G35: 4479 | H35: tanker | I35: ATG | J35: Port Rashid | K35: 4489.3241 | L35: 2007 | M35: 4915.8098
A36: 46079 | B36: West→East | C36: 9925825 | D36: CMA CGM MASAI MARA | E36: 0 | F36: 0 | G36: 75833 | H36: liner | I36: BEL | J36: Mundra | K36: 14853.494 | L36: 2023 | M36: 15076.296
A37: 46077 | B37: East→West | C37: 9925825 | D37: CMA CGM MASAI MARA | E37: 0 | F37: 0 | G37: 75833 | H37: liner | I37: BEL | J37: Jebel Ali | K37: 14853.494 | L37: 2023 | M37: 15076.296
A38: 46076 | B38: West→East | C38: 9789324 | D38: WEPION | E38: 0 | F38: 0 | G38: 28468 | H38: lpg | I38: BEL | J38: Kakinada | K38: 20866.017 | L38: 2018 | M38: 21700.658
A39: 46071 | B39: East→West | C39: 9789324 | D39: WEPION | E39: 0 | F39: 0 | G39: 28468 | H39: lpg | I39: BEL | J39: Ras Al Khair | K39: 20866.017 | L39: 2018 | M39: 21700.658
A40: 46070 | B40: West→East | C40: 9659103 | D40: WAASMUNSTER | E40: 0 | F40: 0 | G40: 28518 | H40: lpg | I40: BEL | J40: Kandla (Deendayal Port) | K40: 20866.017 | L40: 2014 | M40: 22117.978
A41: 46071 | B41: West→East | C41: 9687514 | D41: KORTRIJK | E41: 0 | F41: 0 | G41: 29588 | H41: lpg | I41: BEL | J41: Fujairah | K41: 20866.017 | L41: 2016 | M41: 21909.318
A42: 46076 | B42: West→East | C42: 9719288 | D42: KRUIBEKE | E42: 0 | F42: 0 | G42: 29649 | H42: lpg | I42: BEL | J42: Kandla (Deendayal Port) | K42: 20866.017 | L42: 2017 | M42: 21804.988
A43: 46069 | B43: East→West | C43: 9719288 | D43: KRUIBEKE | E43: 0 | F43: 0 | G43: 29649 | H43: lpg | I43: BEL | J43: Ruwais | K43: 20866.017 | L43: 2017 | M43: 21804.988
A44: 46081 | B44: West→East | C44: 9262168 | D44: BERG 1 | E44: 1 | F44: SANCTIONED FLEET | G44: 299984 | H44: tanker | I44: BEN | J44: China South | K44: 62432.826 | L44: 2004 | M44: 69300.436
A45: 46071 | B45: East→West | C45: 9262168 | D45: BERG 1 | E45: 1 | F45: SANCTIONED FLEET | G45: 299984 | H45: tanker | I45: BEN | J45: World Wide | K45: 62432.826 | L45: 2004 | M45: 69300.436
A46: 46071 | B46: West→East | C46: 9233442 | D46: EMPRESS | E46: 0 | F46: 0 | G46: 51104 | H46: dry | I46: BGD | J46: Karachi | K46: 15035.813 | L46: 2002 | M46: 16840.111
A47: 46071 | B47: East→West | C47: 9771080 | D47: SEAPEAK BAHRAIN | E47: 0 | F47: 0 | G47: 95290 | H47: lng | I47: BHR | J47: Bahrain | K47: 6663.8331 | L47: 2018 | M47: 6930.3864
A48: 46092 | B48: West→East | C48: 8938423 | D48: BAK 8 | E48: 0 | F48: 0 | G48: 2326 | H48: mpp | I48: BHR | J48: World Wide | K48: 2148.7943 | L48: 1996 | M48: 2471.1135
A49: 46073 | B49: West→East | C49: 9236054 | D49: JOVIAN | E49: 0 | F49: 0 | G49: 20601 | H49: chemical | I49: BHS | J49: Singapore | K49: 20866.017 | L49: 2001 | M49: 23474.269
A50: 46068 | B50: East→West | C50: 9236054 | D50: JOVIAN | E50: 0 | F50: 0 | G50: 20601 | H50: chemical | I50: BHS | J50: Jubail | K50: 20866.017 | L50: 2001 | M50: 23474.269
A51: 46077 | B51: East→West | C51: 9367669 | D51: PETALOUDA | E51: 0 | F51: 0 | G51: 47322 | H51: chemoil | I51: BHS | J51: Khor Al Zubair | K51: 20866.017 | L51: 2008 | M51: 22743.959
...

Sheet Emissions proxy
A1: Name | B1: Greenvoyage category | C1: Dwt | D1: Segment | E1: DWT Category | F1: key | G1: Emissions
A2: OCEANA KAI | B2: =_xlfn.XLOOKUP(D2,Mapping!A:A,Mapping!B:B,"CHECK") -> Chemical tanker | C2: 14804 | D2: chemoil | E2: =IF(B2="Chemical tanker", IF(C2<5000,"0-4999", IF(C2<10000,"5000-9999", IF(C2<20000,"10000-19999","20000-+"))), IF(B2="Oil tanker", IF(C2<5000,"0-4999", IF(C2<10000,"5000-9999", IF(C2<20000,"10000-19999", IF(C2<60000,"20000-59999", IF(C2<80000,"60000-79999", IF(C2<120000,"80000-119999", IF(C2<200000,"120000-199999","200000-+"))))))), IF(B2="General cargo", IF(C2<5000,"0-4999", IF(C2<10000,"5000-9999","10000-+")), IF(B2="Bulk carrier", IF(C2<10000,"0-9999", IF(C2<35000,"10000-34999", IF(C2<60000,"35000-59999", IF(C2<100000,"60000-99999", IF(C2<200000,"100000-199999","200000-+"))))), IF(B2="LNG carrier", IF(C2<100000,"0-99999", IF(C2<150000,"100000-149999","150000-+")), "CHECK"))))) -> 10000-19999 | F2: =B2&"|"&E2 -> Chemical tanker|10000-19999 | G2: =_xlfn.XLOOKUP(F2,Mapping!H:H,Mapping!G:G,"CHECK") -> 12170.969
A3: ROYAL A | B3: =_xlfn.XLOOKUP(D3,Mapping!A:A,Mapping!B:B,"CHECK") -> Chemical tanker | C3: 18094 | D3: lpg | E3: =IF(B3="Chemical tanker", IF(C3<5000,"0-4999", IF(C3<10000,"5000-9999", IF(C3<20000,"10000-19999","20000-+"))), IF(B3="Oil tanker", IF(C3<5000,"0-4999", IF(C3<10000,"5000-9999", IF(C3<20000,"10000-19999", IF(C3<60000,"20000-59999", IF(C3<80000,"60000-79999", IF(C3<120000,"80000-119999", IF(C3<200000,"120000-199999","200000-+"))))))), IF(B3="General cargo", IF(C3<5000,"0-4999", IF(C3<10000,"5000-9999","10000-+")), IF(B3="Bulk carrier", IF(C3<10000,"0-9999", IF(C3<35000,"10000-34999", IF(C3<60000,"35000-59999", IF(C3<100000,"60000-99999", IF(C3<200000,"100000-199999","200000-+"))))), IF(B3="LNG carrier", IF(C3<100000,"0-99999", IF(C3<150000,"100000-149999","150000-+")), "CHECK"))))) -> 10000-19999 | F3: =B3&"|"&E3 -> Chemical tanker|10000-19999 | G3: =_xlfn.XLOOKUP(F3,Mapping!H:H,Mapping!G:G,"CHECK") -> 12170.969
A4: XI WANG MU | B4: =_xlfn.XLOOKUP(D4,Mapping!A:A,Mapping!B:B,"CHECK") -> Chemical tanker | C4: 50357 | D4: lpg | E4: =IF(B4="Chemical tanker", IF(C4<5000,"0-4999", IF(C4<10000,"5000-9999", IF(C4<20000,"10000-19999","20000-+"))), IF(B4="Oil tanker", IF(C4<5000,"0-4999", IF(C4<10000,"5000-9999", IF(C4<20000,"10000-19999", IF(C4<60000,"20000-59999", IF(C4<80000,"60000-79999", IF(C4<120000,"80000-119999", IF(C4<200000,"120000-199999","200000-+"))))))), IF(B4="General cargo", IF(C4<5000,"0-4999", IF(C4<10000,"5000-9999","10000-+")), IF(B4="Bulk carrier", IF(C4<10000,"0-9999", IF(C4<35000,"10000-34999", IF(C4<60000,"35000-59999", IF(C4<100000,"60000-99999", IF(C4<200000,"100000-199999","200000-+"))))), IF(B4="LNG carrier", IF(C4<100000,"0-99999", IF(C4<150000,"100000-149999","150000-+")), "CHECK"))))) -> 20000-+ | F4: =B4&"|"&E4 -> Chemical tanker|20000-+ | G4: =_xlfn.XLOOKUP(F4,Mapping!H:H,Mapping!G:G,"CHECK") -> 20866.017
A5: BLOOMING DALE | B5: =_xlfn.XLOOKUP(D5,Mapping!A:A,Mapping!B:B,"CHECK") -> Oil tanker | C5: 12083 | D5: tanker | E5: =IF(B5="Chemical tanker", IF(C5<5000,"0-4999", IF(C5<10000,"5000-9999", IF(C5<20000,"10000-19999","20000-+"))), IF(B5="Oil tanker", IF(C5<5000,"0-4999", IF(C5<10000,"5000-9999", IF(C5<20000,"10000-19999", IF(C5<60000,"20000-59999", IF(C5<80000,"60000-79999", IF(C5<120000,"80000-119999", IF(C5<200000,"120000-199999","200000-+"))))))), IF(B5="General cargo", IF(C5<5000,"0-4999", IF(C5<10000,"5000-9999","10000-+")), IF(B5="Bulk carrier", IF(C5<10000,"0-9999", IF(C5<35000,"10000-34999", IF(C5<60000,"35000-59999", IF(C5<100000,"60000-99999", IF(C5<200000,"100000-199999","200000-+"))))), IF(B5="LNG carrier", IF(C5<100000,"0-99999", IF(C5<150000,"100000-149999","150000-+")), "CHECK"))))) -> 10000-19999 | F5: =B5&"|"&E5 -> Oil tanker|10000-19999 | G5: =_xlfn.XLOOKUP(F5,Mapping!H:H,Mapping!G:G,"CHECK") -> 11412.358
A6: BLOOMING DALE | B6: =_xlfn.XLOOKUP(D6,Mapping!A:A,Mapping!B:B,"CHECK") -> Oil tanker | C6: 12083 | D6: tanker | E6: =IF(B6="Chemical tanker", IF(C6<5000,"0-4999", IF(C6<10000,"5000-9999", IF(C6<20000,"10000-19999","20000-+"))), IF(B6="Oil tanker", IF(C6<5000,"0-4999", IF(C6<10000,"5000-9999", IF(C6<20000,"10000-19999", IF(C6<60000,"20000-59999", IF(C6<80000,"60000-79999", IF(C6<120000,"80000-119999", IF(C6<200000,"120000-199999","200000-+"))))))), IF(B6="General cargo", IF(C6<5000,"0-4999", IF(C6<10000,"5000-9999","10000-+")), IF(B6="Bulk carrier", IF(C6<10000,"0-9999", IF(C6<35000,"10000-34999", IF(C6<60000,"35000-59999", IF(C6<100000,"60000-99999", IF(C6<200000,"100000-199999","200000-+"))))), IF(B6="LNG carrier", IF(C6<100000,"0-99999", IF(C6<150000,"100000-149999","150000-+")), "CHECK"))))) -> 10000-19999 | F6: =B6&"|"&E6 -> Oil tanker|10000-19999 | G6: =_xlfn.XLOOKUP(F6,Mapping!H:H,Mapping!G:G,"CHECK") -> 11412.358
A7: ASTRID 1 | B7: =_xlfn.XLOOKUP(D7,Mapping!A:A,Mapping!B:B,"CHECK") -> Oil tanker | C7: 32950 | D7: tanker | E7: =IF(B7="Chemical tanker", IF(C7<5000,"0-4999", IF(C7<10000,"5000-9999", IF(C7<20000,"10000-19999","20000-+"))), IF(B7="Oil tanker", IF(C7<5000,"0-4999", IF(C7<10000,"5000-9999", IF(C7<20000,"10000-19999", IF(C7<60000,"20000-59999", IF(C7<80000,"60000-79999", IF(C7<120000,"80000-119999", IF(C7<200000,"120000-199999","200000-+"))))))), IF(B7="General cargo", IF(C7<5000,"0-4999", IF(C7<10000,"5000-9999","10000-+")), IF(B7="Bulk carrier", IF(C7<10000,"0-9999", IF(C7<35000,"10000-34999", IF(C7<60000,"35000-59999", IF(C7<100000,"60000-99999", IF(C7<200000,"100000-199999","200000-+"))))), IF(B7="LNG carrier", IF(C7<100000,"0-99999", IF(C7<150000,"100000-149999","150000-+")), "CHECK"))))) -> 20000-59999 | F7: =B7&"|"&E7 -> Oil tanker|20000-59999 | G7: =_xlfn.XLOOKUP(F7,Mapping!H:H,Mapping!G:G,"CHECK") -> 19496.252
A8: STELLANN | B8: =_xlfn.XLOOKUP(D8,Mapping!A:A,Mapping!B:B,"CHECK") -> Oil tanker | C8: 74999 | D8: tanker | E8: =IF(B8="Chemical tanker", IF(C8<5000,"0-4999", IF(C8<10000,"5000-9999", IF(C8<20000,"10000-19999","20000-+"))), IF(B8="Oil tanker", IF(C8<5000,"0-4999", IF(C8<10000,"5000-9999", IF(C8<20000,"10000-19999", IF(C8<60000,"20000-59999", IF(C8<80000,"60000-79999", IF(C8<120000,"80000-119999", IF(C8<200000,"120000-199999","200000-+"))))))), IF(B8="General cargo", IF(C8<5000,"0-4999", IF(C8<10000,"5000-9999","10000-+")), IF(B8="Bulk carrier", IF(C8<10000,"0-9999", IF(C8<35000,"10000-34999", IF(C8<60000,"35000-59999", IF(C8<100000,"60000-99999", IF(C8<200000,"100000-199999","200000-+"))))), IF(B8="LNG carrier", IF(C8<100000,"0-99999", IF(C8<150000,"100000-149999","150000-+")), "CHECK"))))) -> 60000-79999 | F8: =B8&"|"&E8 -> Oil tanker|60000-79999 | G8: =_xlfn.XLOOKUP(F8,Mapping!H:H,Mapping!G:G,"CHECK") -> 26090.7
A9: MARSER | B9: =_xlfn.XLOOKUP(D9,Mapping!A:A,Mapping!B:B,"CHECK") -> Chemical tanker | C9: 49242 | D9: lpg | E9: =IF(B9="Chemical tanker", IF(C9<5000,"0-4999", IF(C9<10000,"5000-9999", IF(C9<20000,"10000-19999","20000-+"))), IF(B9="Oil tanker", IF(C9<5000,"0-4999", IF(C9<10000,"5000-9999", IF(C9<20000,"10000-19999", IF(C9<60000,"20000-59999", IF(C9<80000,"60000-79999", IF(C9<120000,"80000-119999", IF(C9<200000,"120000-199999","200000-+"))))))), IF(B9="General cargo", IF(C9<5000,"0-4999", IF(C9<10000,"5000-9999","10000-+")), IF(B9="Bulk carrier", IF(C9<10000,"0-9999", IF(C9<35000,"10000-34999", IF(C9<60000,"35000-59999", IF(C9<100000,"60000-99999", IF(C9<200000,"100000-199999","200000-+"))))), IF(B9="LNG carrier", IF(C9<100000,"0-99999", IF(C9<150000,"100000-149999","150000-+")), "CHECK"))))) -> 20000-+ | F9: =B9&"|"&E9 -> Chemical tanker|20000-+ | G9: =_xlfn.XLOOKUP(F9,Mapping!H:H,Mapping!G:G,"CHECK") -> 20866.017
A10: MARSER | B10: =_xlfn.XLOOKUP(D10,Mapping!A:A,Mapping!B:B,"CHECK") -> Chemical tanker | C10: 49242 | D10: lpg | E10: =IF(B10="Chemical tanker", IF(C10<5000,"0-4999", IF(C10<10000,"5000-9999", IF(C10<20000,"10000-19999","20000-+"))), IF(B10="Oil tanker", IF(C10<5000,"0-4999", IF(C10<10000,"5000-9999", IF(C10<20000,"10000-19999", IF(C10<60000,"20000-59999", IF(C10<80000,"60000-79999", IF(C10<120000,"80000-119999", IF(C10<200000,"120000-199999","200000-+"))))))), IF(B10="General cargo", IF(C10<5000,"0-4999", IF(C10<10000,"5000-9999","10000-+")), IF(B10="Bulk carrier", IF(C10<10000,"0-9999", IF(C10<35000,"10000-34999", IF(C10<60000,"35000-59999", IF(C10<100000,"60000-99999", IF(C10<200000,"100000-199999","200000-+"))))), IF(B10="LNG carrier", IF(C10<100000,"0-99999", IF(C10<150000,"100000-149999","150000-+")), "CHECK"))))) -> 20000-+ | F10: =B10&"|"&E10 -> Chemical tanker|20000-+ | G10: =_xlfn.XLOOKUP(F10,Mapping!H:H,Mapping!G:G,"CHECK") -> 20866.017
A11: NAVIXON | B11: =_xlfn.XLOOKUP(D11,Mapping!A:A,Mapping!B:B,"CHECK") -> Chemical tanker | C11: 49849 | D11: lpg | E11: =IF(B11="Chemical tanker", IF(C11<5000,"0-4999", IF(C11<10000,"5000-9999", IF(C11<20000,"10000-19999","20000-+"))), IF(B11="Oil tanker", IF(C11<5000,"0-4999", IF(C11<10000,"5000-9999", IF(C11<20000,"10000-19999", IF(C11<60000,"20000-59999", IF(C11<80000,"60000-79999", IF(C11<120000,"80000-119999", IF(C11<200000,"120000-199999","200000-+"))))))), IF(B11="General cargo", IF(C11<5000,"0-4999", IF(C11<10000,"5000-9999","10000-+")), IF(B11="Bulk carrier", IF(C11<10000,"0-9999", IF(C11<35000,"10000-34999", IF(C11<60000,"35000-59999", IF(C11<100000,"60000-99999", IF(C11<200000,"100000-199999","200000-+"))))), IF(B11="LNG carrier", IF(C11<100000,"0-99999", IF(C11<150000,"100000-149999","150000-+")), "CHECK"))))) -> 20000-+ | F11: =B11&"|"&E11 -> Chemical tanker|20000-+ | G11: =_xlfn.XLOOKUP(F11,Mapping!H:H,Mapping!G:G,"CHECK") -> 20866.017
A12: NAVIXON | B12: =_xlfn.XLOOKUP(D12,Mapping!A:A,Mapping!B:B,"CHECK") -> Chemical tanker | C12: 49849 | D12: lpg | E12: =IF(B12="Chemical tanker", IF(C12<5000,"0-4999", IF(C12<10000,"5000-9999", IF(C12<20000,"10000-19999","20000-+"))), IF(B12="Oil tanker", IF(C12<5000,"0-4999", IF(C12<10000,"5000-9999", IF(C12<20000,"10000-19999", IF(C12<60000,"20000-59999", IF(C12<80000,"60000-79999", IF(C12<120000,"80000-119999", IF(C12<200000,"120000-199999","200000-+"))))))), IF(B12="General cargo", IF(C12<5000,"0-4999", IF(C12<10000,"5000-9999","10000-+")), IF(B12="Bulk carrier", IF(C12<10000,"0-9999", IF(C12<35000,"10000-34999", IF(C12<60000,"35000-59999", IF(C12<100000,"60000-99999", IF(C12<200000,"100000-199999","200000-+"))))), IF(B12="LNG carrier", IF(C12<100000,"0-99999", IF(C12<150000,"100000-149999","150000-+")), "CHECK"))))) -> 20000-+ | F12: =B12&"|"&E12 -> Chemical tanker|20000-+ | G12: =_xlfn.XLOOKUP(F12,Mapping!H:H,Mapping!G:G,"CHECK") -> 20866.017
A13: NAVIXON | B13: =_xlfn.XLOOKUP(D13,Mapping!A:A,Mapping!B:B,"CHECK") -> Chemical tanker | C13: 49849 | D13: lpg | E13: =IF(B13="Chemical tanker", IF(C13<5000,"0-4999", IF(C13<10000,"5000-9999", IF(C13<20000,"10000-19999","20000-+"))), IF(B13="Oil tanker", IF(C13<5000,"0-4999", IF(C13<10000,"5000-9999", IF(C13<20000,"10000-19999", IF(C13<60000,"20000-59999", IF(C13<80000,"60000-79999", IF(C13<120000,"80000-119999", IF(C13<200000,"120000-199999","200000-+"))))))), IF(B13="General cargo", IF(C13<5000,"0-4999", IF(C13<10000,"5000-9999","10000-+")), IF(B13="Bulk carrier", IF(C13<10000,"0-9999", IF(C13<35000,"10000-34999", IF(C13<60000,"35000-59999", IF(C13<100000,"60000-99999", IF(C13<200000,"100000-199999","200000-+"))))), IF(B13="LNG carrier", IF(C13<100000,"0-99999", IF(C13<150000,"100000-149999","150000-+")), "CHECK"))))) -> 20000-+ | F13: =B13&"|"&E13 -> Chemical tanker|20000-+ | G13: =_xlfn.XLOOKUP(F13,Mapping!H:H,Mapping!G:G,"CHECK") -> 20866.017
... A46: EMPRESS | B46: =_xlfn.XLOOKUP(D46,Mapping!A:A,Mapping!B:B,"CHECK") -> Bulk carrier | C46: 51104 | D46: dry | E46: =IF(B46="Chemical tanker", IF(C46<5000,"0-4999", IF(C46<10000,"5000-9999", IF(C46<20000,"10000-19999","20000-+"))), IF(B46="Oil tanker", IF(C46<5000,"0-4999", IF(C46<10000,"5000-9999", IF(C46<20000,"10000-19999", IF(C46<60000,"20000-59999", IF(C46<80000,"60000-79999", IF(C46<120000,"80000-119999", IF(C46<200000,"120000-199999","200000-+"))))))), IF(B46="General cargo", IF(C46<5000,"0-4999", IF(C46<10000,"5000-9999","10000-+")), IF(B46="Bulk carrier", IF(C46<10000,"0-9999", IF(C46<35000,"10000-34999", IF(C46<60000,"35000-59999", IF(C46<100000,"60000-99999", IF(C46<200000,"100000-199999","200000-+"))))), IF(B46="LNG carrier", IF(C46<100000,"0-99999", IF(C46<150000,"100000-149999","150000-+")), "CHECK"))))) -> 35000-59999 | F46: =B46&"|"&E46 -> Bulk carrier|35000-59999 | G46: =_xlfn.XLOOKUP(F46,Mapping!H:H,Mapping!G:G,"CHECK") -> 15035.813
A47: SEAPEAK BAHRAIN | B47: =_xlfn.XLOOKUP(D47,Mapping!A:A,Mapping!B:B,"CHECK") -> Other liquids tankers | C47: 95290 | D47: lng | E47: =IF(B47="Chemical tanker", IF(C47<5000,"0-4999", IF(C47<10000,"5000-9999", IF(C47<20000,"10000-19999","20000-+"))), IF(B47="Oil tanker", IF(C47<5000,"0-4999", IF(C47<10000,"5000-9999", IF(C47<20000,"10000-19999", IF(C47<60000,"20000-59999", IF(C47<80000,"60000-79999", IF(C47<120000,"80000-119999", IF(C47<200000,"120000-199999","200000-+"))))))), IF(B47="General cargo", IF(C47<5000,"0-4999", IF(C47<10000,"5000-9999","10000-+")), IF(B47="Bulk carrier", IF(C47<10000,"0-9999", IF(C47<35000,"10000-34999", IF(C47<60000,"35000-59999", IF(C47<100000,"60000-99999", IF(C47<200000,"100000-199999","200000-+"))))), IF(B47="LNG carrier", IF(C47<100000,"0-99999", IF(C47<150000,"100000-149999","150000-+")), "CHECK"))))) -> CHECK | F47: =B47&"|"&E47 -> Other liquids tankers|CHECK | G47: =_xlfn.XLOOKUP(F47,Mapping!H:H,Mapping!G:G,_xlfn.NUMBERVALUE(6663.83312179978)) -> 6663.8331
A48: BAK 8 | B48: =_xlfn.XLOOKUP(D48,Mapping!A:A,Mapping!B:B,"CHECK") -> General cargo | C48: 2326 | D48: mpp | E48: =IF(B48="Chemical tanker", IF(C48<5000,"0-4999", IF(C48<10000,"5000-9999", IF(C48<20000,"10000-19999","20000-+"))), IF(B48="Oil tanker", IF(C48<5000,"0-4999", IF(C48<10000,"5000-9999", IF(C48<20000,"10000-19999", IF(C48<60000,"20000-59999", IF(C48<80000,"60000-79999", IF(C48<120000,"80000-119999", IF(C48<200000,"120000-199999","200000-+"))))))), IF(B48="General cargo", IF(C48<5000,"0-4999", IF(C48<10000,"5000-9999","10000-+")), IF(B48="Bulk carrier", IF(C48<10000,"0-9999", IF(C48<35000,"10000-34999", IF(C48<60000,"35000-59999", IF(C48<100000,"60000-99999", IF(C48<200000,"100000-199999","200000-+"))))), IF(B48="LNG carrier", IF(C48<100000,"0-99999", IF(C48<150000,"100000-149999","150000-+")), "CHECK"))))) -> 0-4999 | F48: =B48&"|"&E48 -> General cargo|0-4999 | G48: =_xlfn.XLOOKUP(F48,Mapping!H:H,Mapping!G:G,"CHECK") -> 2148.7943
A49: JOVIAN | B49: =_xlfn.XLOOKUP(D49,Mapping!A:A,Mapping!B:B,"CHECK") -> Chemical tanker | C49: 20601 | D49: chemical | E49: =IF(B49="Chemical tanker", IF(C49<5000,"0-4999", IF(C49<10000,"5000-9999", IF(C49<20000,"10000-19999","20000-+"))), IF(B49="Oil tanker", IF(C49<5000,"0-4999", IF(C49<10000,"5000-9999", IF(C49<20000,"10000-19999", IF(C49<60000,"20000-59999", IF(C49<80000,"60000-79999", IF(C49<120000,"80000-119999", IF(C49<200000,"120000-199999","200000-+"))))))), IF(B49="General cargo", IF(C49<5000,"0-4999", IF(C49<10000,"5000-9999","10000-+")), IF(B49="Bulk carrier", IF(C49<10000,"0-9999", IF(C49<35000,"10000-34999", IF(C49<60000,"35000-59999", IF(C49<100000,"60000-99999", IF(C49<200000,"100000-199999","200000-+"))))), IF(B49="LNG carrier", IF(C49<100000,"0-99999", IF(C49<150000,"100000-149999","150000-+")), "CHECK"))))) -> 20000-+ | F49: =B49&"|"&E49 -> Chemical tanker|20000-+ | G49: =_xlfn.XLOOKUP(F49,Mapping!H:H,Mapping!G:G,"CHECK") -> 20866.017
A50: JOVIAN | B50: =_xlfn.XLOOKUP(D50,Mapping!A:A,Mapping!B:B,"CHECK") -> Chemical tanker | C50: 20601 | D50: chemical | E50: =IF(B50="Chemical tanker", IF(C50<5000,"0-4999", IF(C50<10000,"5000-9999", IF(C50<20000,"10000-19999","20000-+"))), IF(B50="Oil tanker", IF(C50<5000,"0-4999", IF(C50<10000,"5000-9999", IF(C50<20000,"10000-19999", IF(C50<60000,"20000-59999", IF(C50<80000,"60000-79999", IF(C50<120000,"80000-119999", IF(C50<200000,"120000-199999","200000-+"))))))), IF(B50="General cargo", IF(C50<5000,"0-4999", IF(C50<10000,"5000-9999","10000-+")), IF(B50="Bulk carrier", IF(C50<10000,"0-9999", IF(C50<35000,"10000-34999", IF(C50<60000,"35000-59999", IF(C50<100000,"60000-99999", IF(C50<200000,"100000-199999","200000-+"))))), IF(B50="LNG carrier", IF(C50<100000,"0-99999", IF(C50<150000,"100000-149999","150000-+")), "CHECK"))))) -> 20000-+ | F50: =B50&"|"&E50 -> Chemical tanker|20000-+ | G50: =_xlfn.XLOOKUP(F50,Mapping!H:H,Mapping!G:G,"CHECK") -> 20866.017
A51: PETALOUDA | B51: =_xlfn.XLOOKUP(D51,Mapping!A:A,Mapping!B:B,"CHECK") -> Chemical tanker | C51: 47322 | D51: chemoil | E51: =IF(B51="Chemical tanker", IF(C51<5000,"0-4999", IF(C51<10000,"5000-9999", IF(C51<20000,"10000-19999","20000-+"))), IF(B51="Oil tanker", IF(C51<5000,"0-4999", IF(C51<10000,"5000-9999", IF(C51<20000,"10000-19999", IF(C51<60000,"20000-59999", IF(C51<80000,"60000-79999", IF(C51<120000,"80000-119999", IF(C51<200000,"120000-199999","200000-+"))))))), IF(B51="General cargo", IF(C51<5000,"0-4999", IF(C51<10000,"5000-9999","10000-+")), IF(B51="Bulk carrier", IF(C51<10000,"0-9999", IF(C51<35000,"10000-34999", IF(C51<60000,"35000-59999", IF(C51<100000,"60000-99999", IF(C51<200000,"100000-199999","200000-+"))))), IF(B51="LNG carrier", IF(C51<100000,"0-99999", IF(C51<150000,"100000-149999","150000-+")), "CHECK"))))) -> 20000-+ | F51: =B51&"|"&E51 -> Chemical tanker|20000-+ | G51: =_xlfn.XLOOKUP(F51,Mapping!H:H,Mapping!G:G,"CHECK") -> 20866.017
A52: LADY ANASTASIA | B52: =_xlfn.XLOOKUP(D52,Mapping!A:A,Mapping!B:B,"CHECK") -> Bulk carrier | C52: 36845 | D52: dry | E52: =IF(B52="Chemical tanker", IF(C52<5000,"0-4999", IF(C52<10000,"5000-9999", IF(C52<20000,"10000-19999","20000-+"))), IF(B52="Oil tanker", IF(C52<5000,"0-4999", IF(C52<10000,"5000-9999", IF(C52<20000,"10000-19999", IF(C52<60000,"20000-59999", IF(C52<80000,"60000-79999", IF(C52<120000,"80000-119999", IF(C52<200000,"120000-199999","200000-+"))))))), IF(B52="General cargo", IF(C52<5000,"0-4999", IF(C52<10000,"5000-9999","10000-+")), IF(B52="Bulk carrier", IF(C52<10000,"0-9999", IF(C52<35000,"10000-34999", IF(C52<60000,"35000-59999", IF(C52<100000,"60000-99999", IF(C52<200000,"100000-199999","200000-+"))))), IF(B52="LNG carrier", IF(C52<100000,"0-99999", IF(C52<150000,"100000-149999","150000-+")), "CHECK"))))) -> 35000-59999 | F52: =B52&"|"&E52 -> Bulk carrier|35000-59999 | G52: =_xlfn.XLOOKUP(F52,Mapping!H:H,Mapping!G:G,"CHECK") -> 15035.813
A53: AFRICAN TOUCAN | B53: =_xlfn.XLOOKUP(D53,Mapping!A:A,Mapping!B:B,"CHECK") -> Bulk carrier | C53: 37730 | D53: dry | E53: =IF(B53="Chemical tanker", IF(C53<5000,"0-4999", IF(C53<10000,"5000-9999", IF(C53<20000,"10000-19999","20000-+"))), IF(B53="Oil tanker", IF(C53<5000,"0-4999", IF(C53<10000,"5000-9999", IF(C53<20000,"10000-19999", IF(C53<60000,"20000-59999", IF(C53<80000,"60000-79999", IF(C53<120000,"80000-119999", IF(C53<200000,"120000-199999","200000-+"))))))), IF(B53="General cargo", IF(C53<5000,"0-4999", IF(C53<10000,"5000-9999","10000-+")), IF(B53="Bulk carrier", IF(C53<10000,"0-9999", IF(C53<35000,"10000-34999", IF(C53<60000,"35000-59999", IF(C53<100000,"60000-99999", IF(C53<200000,"100000-199999","200000-+"))))), IF(B53="LNG carrier", IF(C53<100000,"0-99999", IF(C53<150000,"100000-149999","150000-+")), "CHECK"))))) -> 35000-59999 | F53: =B53&"|"&E53 -> Bulk carrier|35000-59999 | G53: =_xlfn.XLOOKUP(F53,Mapping!H:H,Mapping!G:G,"CHECK") -> 15035.813
A54: AFRICAN TOUCAN | B54: =_xlfn.XLOOKUP(D54,Mapping!A:A,Mapping!B:B,"CHECK") -> Bulk carrier | C54: 37730 | D54: dry | E54: =IF(B54="Chemical tanker", IF(C54<5000,"0-4999", IF(C54<10000,"5000-9999", IF(C54<20000,"10000-19999","20000-+"))), IF(B54="Oil tanker", IF(C54<5000,"0-4999", IF(C54<10000,"5000-9999", IF(C54<20000,"10000-19999", IF(C54<60000,"20000-59999", IF(C54<80000,"60000-79999", IF(C54<120000,"80000-119999", IF(C54<200000,"120000-199999","200000-+"))))))), IF(B54="General cargo", IF(C54<5000,"0-4999", IF(C54<10000,"5000-9999","10000-+")), IF(B54="Bulk carrier", IF(C54<10000,"0-9999", IF(C54<35000,"10000-34999", IF(C54<60000,"35000-59999", IF(C54<100000,"60000-99999", IF(C54<200000,"100000-199999","200000-+"))))), IF(B54="LNG carrier", IF(C54<100000,"0-99999", IF(C54<150000,"100000-149999","150000-+")), "CHECK"))))) -> 35000-59999 | F54: =B54&"|"&E54 -> Bulk carrier|35000-59999 | G54: =_xlfn.XLOOKUP(F54,Mapping!H:H,Mapping!G:G,"CHECK") -> 15035.813
A55: AFRICAN RAPTOR | B55: =_xlfn.XLOOKUP(D55,Mapping!A:A,Mapping!B:B,"CHECK") -> Bulk carrier | C55: 61286 | D55: dry | E55: =IF(B55="Chemical tanker", IF(C55<5000,"0-4999", IF(C55<10000,"5000-9999", IF(C55<20000,"10000-19999","20000-+"))), IF(B55="Oil tanker", IF(C55<5000,"0-4999", IF(C55<10000,"5000-9999", IF(C55<20000,"10000-19999", IF(C55<60000,"20000-59999", IF(C55<80000,"60000-79999", IF(C55<120000,"80000-119999", IF(C55<200000,"120000-199999","200000-+"))))))), IF(B55="General cargo", IF(C55<5000,"0-4999", IF(C55<10000,"5000-9999","10000-+")), IF(B55="Bulk carrier", IF(C55<10000,"0-9999", IF(C55<35000,"10000-34999", IF(C55<60000,"35000-59999", IF(C55<100000,"60000-99999", IF(C55<200000,"100000-199999","200000-+"))))), IF(B55="LNG carrier", IF(C55<100000,"0-99999", IF(C55<150000,"100000-149999","150000-+")), "CHECK"))))) -> 60000-99999 | F55: =B55&"|"&E55 -> Bulk carrier|60000-99999 | G55: =_xlfn.XLOOKUP(F55,Mapping!H:H,Mapping!G:G,"CHECK") -> 21117.137
A56: AFRICAN RAPTOR | B56: =_xlfn.XLOOKUP(D56,Mapping!A:A,Mapping!B:B,"CHECK") -> Bulk carrier | C56: 61286 | D56: dry | E56: =IF(B56="Chemical tanker", IF(C56<5000,"0-4999", IF(C56<10000,"5000-9999", IF(C56<20000,"10000-19999","20000-+"))), IF(B56="Oil tanker", IF(C56<5000,"0-4999", IF(C56<10000,"5000-9999", IF(C56<20000,"10000-19999", IF(C56<60000,"20000-59999", IF(C56<80000,"60000-79999", IF(C56<120000,"80000-119999", IF(C56<200000,"120000-199999","200000-+"))))))), IF(B56="General cargo", IF(C56<5000,"0-4999", IF(C56<10000,"5000-9999","10000-+")), IF(B56="Bulk carrier", IF(C56<10000,"0-9999", IF(C56<35000,"10000-34999", IF(C56<60000,"35000-59999", IF(C56<100000,"60000-99999", IF(C56<200000,"100000-199999","200000-+"))))), IF(B56="LNG carrier", IF(C56<100000,"0-99999", IF(C56<150000,"100000-149999","150000-+")), "CHECK"))))) -> 60000-99999 | F56: =B56&"|"&E56 -> Bulk carrier|60000-99999 | G56: =_xlfn.XLOOKUP(F56,Mapping!H:H,Mapping!G:G,"CHECK") -> 21117.137
A57: AFRICAN AVOCET | B57: =_xlfn.XLOOKUP(D57,Mapping!A:A,Mapping!B:B,"CHECK") -> Bulk carrier | C57: 61328 | D57: dry | E57: =IF(B57="Chemical tanker", IF(C57<5000,"0-4999", IF(C57<10000,"5000-9999", IF(C57<20000,"10000-19999","20000-+"))), IF(B57="Oil tanker", IF(C57<5000,"0-4999", IF(C57<10000,"5000-9999", IF(C57<20000,"10000-19999", IF(C57<60000,"20000-59999", IF(C57<80000,"60000-79999", IF(C57<120000,"80000-119999", IF(C57<200000,"120000-199999","200000-+"))))))), IF(B57="General cargo", IF(C57<5000,"0-4999", IF(C57<10000,"5000-9999","10000-+")), IF(B57="Bulk carrier", IF(C57<10000,"0-9999", IF(C57<35000,"10000-34999", IF(C57<60000,"35000-59999", IF(C57<100000,"60000-99999", IF(C57<200000,"100000-199999","200000-+"))))), IF(B57="LNG carrier", IF(C57<100000,"0-99999", IF(C57<150000,"100000-149999","150000-+")), "CHECK"))))) -> 60000-99999 | F57: =B57&"|"&E57 -> Bulk carrier|60000-99999 | G57: =_xlfn.XLOOKUP(F57,Mapping!H:H,Mapping!G:G,"CHECK") -> 21117.137
A58: ASTRO NEMBUS | B58: =_xlfn.XLOOKUP(D58,Mapping!A:A,Mapping!B:B,"CHECK") -> Bulk carrier | C58: 63510 | D58: dry | E58: =IF(B58="Chemical tanker", IF(C58<5000,"0-4999", IF(C58<10000,"5000-9999", IF(C58<20000,"10000-19999","20000-+"))), IF(B58="Oil tanker", IF(C58<5000,"0-4999", IF(C58<10000,"5000-9999", IF(C58<20000,"10000-19999", IF(C58<60000,"20000-59999", IF(C58<80000,"60000-79999", IF(C58<120000,"80000-119999", IF(C58<200000,"120000-199999","200000-+"))))))), IF(B58="General cargo", IF(C58<5000,"0-4999", IF(C58<10000,"5000-9999","10000-+")), IF(B58="Bulk carrier", IF(C58<10000,"0-9999", IF(C58<35000,"10000-34999", IF(C58<60000,"35000-59999", IF(C58<100000,"60000-99999", IF(C58<200000,"100000-199999","200000-+"))))), IF(B58="LNG carrier", IF(C58<100000,"0-99999", IF(C58<150000,"100000-149999","150000-+")), "CHECK"))))) -> 60000-99999 | F58: =B58&"|"&E58 -> Bulk carrier|60000-99999 | G58: =_xlfn.XLOOKUP(F58,Mapping!H:H,Mapping!G:G,"CHECK") -> 21117.137
A59: ASTRO NEMBUS | B59: =_xlfn.XLOOKUP(D59,Mapping!A:A,Mapping!B:B,"CHECK") -> Bulk carrier | C59: 63510 | D59: dry | E59: =IF(B59="Chemical tanker", IF(C59<5000,"0-4999", IF(C59<10000,"5000-9999", IF(C59<20000,"10000-19999","20000-+"))), IF(B59="Oil tanker", IF(C59<5000,"0-4999", IF(C59<10000,"5000-9999", IF(C59<20000,"10000-19999", IF(C59<60000,"20000-59999", IF(C59<80000,"60000-79999", IF(C59<120000,"80000-119999", IF(C59<200000,"120000-199999","200000-+"))))))), IF(B59="General cargo", IF(C59<5000,"0-4999", IF(C59<10000,"5000-9999","10000-+")), IF(B59="Bulk carrier", IF(C59<10000,"0-9999", IF(C59<35000,"10000-34999", IF(C59<60000,"35000-59999", IF(C59<100000,"60000-99999", IF(C59<200000,"100000-199999","200000-+"))))), IF(B59="LNG carrier", IF(C59<100000,"0-99999", IF(C59<150000,"100000-149999","150000-+")), "CHECK"))))) -> 60000-99999 | F59: =B59&"|"&E59 -> Bulk carrier|60000-99999 | G59: =_xlfn.XLOOKUP(F59,Mapping!H:H,Mapping!G:G,"CHECK") -> 21117.137
... A64: CMA CGM MARCO POLO | B64: =_xlfn.XLOOKUP(D64,Mapping!A:A,Mapping!B:B,"CHECK") -> General cargo | C64: 187625 | D64: liner | E64: =IF(B64="Chemical tanker", IF(C64<5000,"0-4999", IF(C64<10000,"5000-9999", IF(C64<20000,"10000-19999","20000-+"))), IF(B64="Oil tanker", IF(C64<5000,"0-4999", IF(C64<10000,"5000-9999", IF(C64<20000,"10000-19999", IF(C64<60000,"20000-59999", IF(C64<80000,"60000-79999", IF(C64<120000,"80000-119999", IF(C64<200000,"120000-199999","200000-+"))))))), IF(B64="General cargo", IF(C64<5000,"0-4999", IF(C64<10000,"5000-9999","10000-+")), IF(B64="Bulk carrier", IF(C64<10000,"0-9999", IF(C64<35000,"10000-34999", IF(C64<60000,"35000-59999", IF(C64<100000,"60000-99999", IF(C64<200000,"100000-199999","200000-+"))))), IF(B64="LNG carrier", IF(C64<100000,"0-99999", IF(C64<150000,"100000-149999","150000-+")), "CHECK"))))) -> 10000-+ | F64: =B64&"|"&E64 -> General cargo|10000-+ | G64: =_xlfn.XLOOKUP(F64,Mapping!H:H,Mapping!G:G,"CHECK") -> 14853.494
A65: LUSAIL | B65: =_xlfn.XLOOKUP(D65,Mapping!A:A,Mapping!B:B,"CHECK") -> Other liquids tankers | C65: 78489 | D65: lng | E65: =IF(B65="Chemical tanker", IF(C65<5000,"0-4999", IF(C65<10000,"5000-9999", IF(C65<20000,"10000-19999","20000-+"))), IF(B65="Oil tanker", IF(C65<5000,"0-4999", IF(C65<10000,"5000-9999", IF(C65<20000,"10000-19999", IF(C65<60000,"20000-59999", IF(C65<80000,"60000-79999", IF(C65<120000,"80000-119999", IF(C65<200000,"120000-199999","200000-+"))))))), IF(B65="General cargo", IF(C65<5000,"0-4999", IF(C65<10000,"5000-9999","10000-+")), IF(B65="Bulk carrier", IF(C65<10000,"0-9999", IF(C65<35000,"10000-34999", IF(C65<60000,"35000-59999", IF(C65<100000,"60000-99999", IF(C65<200000,"100000-199999","200000-+"))))), IF(B65="LNG carrier", IF(C65<100000,"0-99999", IF(C65<150000,"100000-149999","150000-+")), "CHECK"))))) -> CHECK | F65: =B65&"|"&E65 -> Other liquids tankers|CHECK | G65: =_xlfn.XLOOKUP(F65,Mapping!H:H,Mapping!G:G,_xlfn.NUMBERVALUE(6663.83312179978)) -> 6663.8331
A66: LUSAIL | B66: =_xlfn.XLOOKUP(D66,Mapping!A:A,Mapping!B:B,"CHECK") -> Other liquids tankers | C66: 78489 | D66: lng | E66: =IF(B66="Chemical tanker", IF(C66<5000,"0-4999", IF(C66<10000,"5000-9999", IF(C66<20000,"10000-19999","20000-+"))), IF(B66="Oil tanker", IF(C66<5000,"0-4999", IF(C66<10000,"5000-9999", IF(C66<20000,"10000-19999", IF(C66<60000,"20000-59999", IF(C66<80000,"60000-79999", IF(C66<120000,"80000-119999", IF(C66<200000,"120000-199999","200000-+"))))))), IF(B66="General cargo", IF(C66<5000,"0-4999", IF(C66<10000,"5000-9999","10000-+")), IF(B66="Bulk carrier", IF(C66<10000,"0-9999", IF(C66<35000,"10000-34999", IF(C66<60000,"35000-59999", IF(C66<100000,"60000-99999", IF(C66<200000,"100000-199999","200000-+"))))), IF(B66="LNG carrier", IF(C66<100000,"0-99999", IF(C66<150000,"100000-149999","150000-+")), "CHECK"))))) -> CHECK | F66: =B66&"|"&E66 -> Other liquids tankers|CHECK | G66: =_xlfn.XLOOKUP(F66,Mapping!H:H,Mapping!G:G,_xlfn.NUMBERVALUE(6663.83312179978)) -> 6663.8331
A67: AL THAKHIRA | B67: =_xlfn.XLOOKUP(D67,Mapping!A:A,Mapping!B:B,"CHECK") -> Other liquids tankers | C67: 78542 | D67: lng | E67: =IF(B67="Chemical tanker", IF(C67<5000,"0-4999", IF(C67<10000,"5000-9999", IF(C67<20000,"10000-19999","20000-+"))), IF(B67="Oil tanker", IF(C67<5000,"0-4999", IF(C67<10000,"5000-9999", IF(C67<20000,"10000-19999", IF(C67<60000,"20000-59999", IF(C67<80000,"60000-79999", IF(C67<120000,"80000-119999", IF(C67<200000,"120000-199999","200000-+"))))))), IF(B67="General cargo", IF(C67<5000,"0-4999", IF(C67<10000,"5000-9999","10000-+")), IF(B67="Bulk carrier", IF(C67<10000,"0-9999", IF(C67<35000,"10000-34999", IF(C67<60000,"35000-59999", IF(C67<100000,"60000-99999", IF(C67<200000,"100000-199999","200000-+"))))), IF(B67="LNG carrier", IF(C67<100000,"0-99999", IF(C67<150000,"100000-149999","150000-+")), "CHECK"))))) -> CHECK | F67: =B67&"|"&E67 -> Other liquids tankers|CHECK | G67: =_xlfn.XLOOKUP(F67,Mapping!H:H,Mapping!G:G,_xlfn.NUMBERVALUE(6663.83312179978)) -> 6663.8331
A68: AL THAKHIRA | B68: =_xlfn.XLOOKUP(D68,Mapping!A:A,Mapping!B:B,"CHECK") -> Other liquids tankers | C68: 78542 | D68: lng | E68: =IF(B68="Chemical tanker", IF(C68<5000,"0-4999", IF(C68<10000,"5000-9999", IF(C68<20000,"10000-19999","20000-+"))), IF(B68="Oil tanker", IF(C68<5000,"0-4999", IF(C68<10000,"5000-9999", IF(C68<20000,"10000-19999", IF(C68<60000,"20000-59999", IF(C68<80000,"60000-79999", IF(C68<120000,"80000-119999", IF(C68<200000,"120000-199999","200000-+"))))))), IF(B68="General cargo", IF(C68<5000,"0-4999", IF(C68<10000,"5000-9999","10000-+")), IF(B68="Bulk carrier", IF(C68<10000,"0-9999", IF(C68<35000,"10000-34999", IF(C68<60000,"35000-59999", IF(C68<100000,"60000-99999", IF(C68<200000,"100000-199999","200000-+"))))), IF(B68="LNG carrier", IF(C68<100000,"0-99999", IF(C68<150000,"100000-149999","150000-+")), "CHECK"))))) -> CHECK | F68: =B68&"|"&E68 -> Other liquids tankers|CHECK | G68: =_xlfn.XLOOKUP(F68,Mapping!H:H,Mapping!G:G,_xlfn.NUMBERVALUE(6663.83312179978)) -> 6663.8331
A69: AL DEEBEL | B69: =_xlfn.XLOOKUP(D69,Mapping!A:A,Mapping!B:B,"CHECK") -> Other liquids tankers | C69: 78594 | D69: lng | E69: =IF(B69="Chemical tanker", IF(C69<5000,"0-4999", IF(C69<10000,"5000-9999", IF(C69<20000,"10000-19999","20000-+"))), IF(B69="Oil tanker", IF(C69<5000,"0-4999", IF(C69<10000,"5000-9999", IF(C69<20000,"10000-19999", IF(C69<60000,"20000-59999", IF(C69<80000,"60000-79999", IF(C69<120000,"80000-119999", IF(C69<200000,"120000-199999","200000-+"))))))), IF(B69="General cargo", IF(C69<5000,"0-4999", IF(C69<10000,"5000-9999","10000-+")), IF(B69="Bulk carrier", IF(C69<10000,"0-9999", IF(C69<35000,"10000-34999", IF(C69<60000,"35000-59999", IF(C69<100000,"60000-99999", IF(C69<200000,"100000-199999","200000-+"))))), IF(B69="LNG carrier", IF(C69<100000,"0-99999", IF(C69<150000,"100000-149999","150000-+")), "CHECK"))))) -> CHECK | F69: =B69&"|"&E69 -> Other liquids tankers|CHECK | G69: =_xlfn.XLOOKUP(F69,Mapping!H:H,Mapping!G:G,_xlfn.NUMBERVALUE(6663.83312179978)) -> 6663.8331
A70: AL KHARSAAH | B70: =_xlfn.XLOOKUP(D70,Mapping!A:A,Mapping!B:B,"CHECK") -> Other liquids tankers | C70: 116268 | D70: lng | E70: =IF(B70="Chemical tanker", IF(C70<5000,"0-4999", IF(C70<10000,"5000-9999", IF(C70<20000,"10000-19999","20000-+"))), IF(B70="Oil tanker", IF(C70<5000,"0-4999", IF(C70<10000,"5000-9999", IF(C70<20000,"10000-19999", IF(C70<60000,"20000-59999", IF(C70<80000,"60000-79999", IF(C70<120000,"80000-119999", IF(C70<200000,"120000-199999","200000-+"))))))), IF(B70="General cargo", IF(C70<5000,"0-4999", IF(C70<10000,"5000-9999","10000-+")), IF(B70="Bulk carrier", IF(C70<10000,"0-9999", IF(C70<35000,"10000-34999", IF(C70<60000,"35000-59999", IF(C70<100000,"60000-99999", IF(C70<200000,"100000-199999","200000-+"))))), IF(B70="LNG carrier", IF(C70<100000,"0-99999", IF(C70<150000,"100000-149999","150000-+")), "CHECK"))))) -> CHECK | F70: =B70&"|"&E70 -> Other liquids tankers|CHECK | G70: =_xlfn.XLOOKUP(F70,Mapping!H:H,Mapping!G:G,_xlfn.NUMBERVALUE(6663.83312179978)) -> 6663.8331
A71: DUHAIL | B71: =_xlfn.XLOOKUP(D71,Mapping!A:A,Mapping!B:B,"CHECK") -> Other liquids tankers | C71: 121639 | D71: lng | E71: =IF(B71="Chemical tanker", IF(C71<5000,"0-4999", IF(C71<10000,"5000-9999", IF(C71<20000,"10000-19999","20000-+"))), IF(B71="Oil tanker", IF(C71<5000,"0-4999", IF(C71<10000,"5000-9999", IF(C71<20000,"10000-19999", IF(C71<60000,"20000-59999", IF(C71<80000,"60000-79999", IF(C71<120000,"80000-119999", IF(C71<200000,"120000-199999","200000-+"))))))), IF(B71="General cargo", IF(C71<5000,"0-4999", IF(C71<10000,"5000-9999","10000-+")), IF(B71="Bulk carrier", IF(C71<10000,"0-9999", IF(C71<35000,"10000-34999", IF(C71<60000,"35000-59999", IF(C71<100000,"60000-99999", IF(C71<200000,"100000-199999","200000-+"))))), IF(B71="LNG carrier", IF(C71<100000,"0-99999", IF(C71<150000,"100000-149999","150000-+")), "CHECK"))))) -> CHECK | F71: =B71&"|"&E71 -> Other liquids tankers|CHECK | G71: =_xlfn.XLOOKUP(F71,Mapping!H:H,Mapping!G:G,_xlfn.NUMBERVALUE(6663.83312179978)) -> 6663.8331
A72: AFRICAN KESTREL | B72: =_xlfn.XLOOKUP(D72,Mapping!A:A,Mapping!B:B,"CHECK") -> General cargo | C72: 37787 | D72: mpp | E72: =IF(B72="Chemical tanker", IF(C72<5000,"0-4999", IF(C72<10000,"5000-9999", IF(C72<20000,"10000-19999","20000-+"))), IF(B72="Oil tanker", IF(C72<5000,"0-4999", IF(C72<10000,"5000-9999", IF(C72<20000,"10000-19999", IF(C72<60000,"20000-59999", IF(C72<80000,"60000-79999", IF(C72<120000,"80000-119999", IF(C72<200000,"120000-199999","200000-+"))))))), IF(B72="General cargo", IF(C72<5000,"0-4999", IF(C72<10000,"5000-9999","10000-+")), IF(B72="Bulk carrier", IF(C72<10000,"0-9999", IF(C72<35000,"10000-34999", IF(C72<60000,"35000-59999", IF(C72<100000,"60000-99999", IF(C72<200000,"100000-199999","200000-+"))))), IF(B72="LNG carrier", IF(C72<100000,"0-99999", IF(C72<150000,"100000-149999","150000-+")), "CHECK"))))) -> 10000-+ | F72: =B72&"|"&E72 -> General cargo|10000-+ | G72: =_xlfn.XLOOKUP(F72,Mapping!H:H,Mapping!G:G,"CHECK") -> 14853.494
A73: SAGA HORIZON | B73: =_xlfn.XLOOKUP(D73,Mapping!A:A,Mapping!B:B,"CHECK") -> General cargo | C73: 47016 | D73: mpp | E73: =IF(B73="Chemical tanker", IF(C73<5000,"0-4999", IF(C73<10000,"5000-9999", IF(C73<20000,"10000-19999","20000-+"))), IF(B73="Oil tanker", IF(C73<5000,"0-4999", IF(C73<10000,"5000-9999", IF(C73<20000,"10000-19999", IF(C73<60000,"20000-59999", IF(C73<80000,"60000-79999", IF(C73<120000,"80000-119999", IF(C73<200000,"120000-199999","200000-+"))))))), IF(B73="General cargo", IF(C73<5000,"0-4999", IF(C73<10000,"5000-9999","10000-+")), IF(B73="Bulk carrier", IF(C73<10000,"0-9999", IF(C73<35000,"10000-34999", IF(C73<60000,"35000-59999", IF(C73<100000,"60000-99999", IF(C73<200000,"100000-199999","200000-+"))))), IF(B73="LNG carrier", IF(C73<100000,"0-99999", IF(C73<150000,"100000-149999","150000-+")), "CHECK"))))) -> 10000-+ | F73: =B73&"|"&E73 -> General cargo|10000-+ | G73: =_xlfn.XLOOKUP(F73,Mapping!H:H,Mapping!G:G,"CHECK") -> 14853.494
A74: SWIFT ACE | B74: =_xlfn.XLOOKUP(D74,Mapping!A:A,Mapping!B:B,"CHECK") -> General cargo | C74: 18865 | D74: pctc | E74: =IF(B74="Chemical tanker", IF(C74<5000,"0-4999", IF(C74<10000,"5000-9999", IF(C74<20000,"10000-19999","20000-+"))), IF(B74="Oil tanker", IF(C74<5000,"0-4999", IF(C74<10000,"5000-9999", IF(C74<20000,"10000-19999", IF(C74<60000,"20000-59999", IF(C74<80000,"60000-79999", IF(C74<120000,"80000-119999", IF(C74<200000,"120000-199999","200000-+"))))))), IF(B74="General cargo", IF(C74<5000,"0-4999", IF(C74<10000,"5000-9999","10000-+")), IF(B74="Bulk carrier", IF(C74<10000,"0-9999", IF(C74<35000,"10000-34999", IF(C74<60000,"35000-59999", IF(C74<100000,"60000-99999", IF(C74<200000,"100000-199999","200000-+"))))), IF(B74="LNG carrier", IF(C74<100000,"0-99999", IF(C74<150000,"100000-149999","150000-+")), "CHECK"))))) -> 10000-+ | F74: =B74&"|"&E74 -> General cargo|10000-+ | G74: =_xlfn.XLOOKUP(F74,Mapping!H:H,Mapping!G:G,"CHECK") -> 14853.494
A75: LYRIC MAGNOLIA | B75: =_xlfn.XLOOKUP(D75,Mapping!A:A,Mapping!B:B,"CHECK") -> Oil tanker | C75: 109999 | D75: tanker | E75: =IF(B75="Chemical tanker", IF(C75<5000,"0-4999", IF(C75<10000,"5000-9999", IF(C75<20000,"10000-19999","20000-+"))), IF(B75="Oil tanker", IF(C75<5000,"0-4999", IF(C75<10000,"5000-9999", IF(C75<20000,"10000-19999", IF(C75<60000,"20000-59999", IF(C75<80000,"60000-79999", IF(C75<120000,"80000-119999", IF(C75<200000,"120000-199999","200000-+"))))))), IF(B75="General cargo", IF(C75<5000,"0-4999", IF(C75<10000,"5000-9999","10000-+")), IF(B75="Bulk carrier", IF(C75<10000,"0-9999", IF(C75<35000,"10000-34999", IF(C75<60000,"35000-59999", IF(C75<100000,"60000-99999", IF(C75<200000,"100000-199999","200000-+"))))), IF(B75="LNG carrier", IF(C75<100000,"0-99999", IF(C75<150000,"100000-149999","150000-+")), "CHECK"))))) -> 80000-119999 | F75: =B75&"|"&E75 -> Oil tanker|80000-119999 | G75: =_xlfn.XLOOKUP(F75,Mapping!H:H,Mapping!G:G,"CHECK") -> 28821.516
A76: LYRIC MAGNOLIA | B76: =_xlfn.XLOOKUP(D76,Mapping!A:A,Mapping!B:B,"CHECK") -> Oil tanker | C76: 109999 | D76: tanker | E76: =IF(B76="Chemical tanker", IF(C76<5000,"0-4999", IF(C76<10000,"5000-9999", IF(C76<20000,"10000-19999","20000-+"))), IF(B76="Oil tanker", IF(C76<5000,"0-4999", IF(C76<10000,"5000-9999", IF(C76<20000,"10000-19999", IF(C76<60000,"20000-59999", IF(C76<80000,"60000-79999", IF(C76<120000,"80000-119999", IF(C76<200000,"120000-199999","200000-+"))))))), IF(B76="General cargo", IF(C76<5000,"0-4999", IF(C76<10000,"5000-9999","10000-+")), IF(B76="Bulk carrier", IF(C76<10000,"0-9999", IF(C76<35000,"10000-34999", IF(C76<60000,"35000-59999", IF(C76<100000,"60000-99999", IF(C76<200000,"100000-199999","200000-+"))))), IF(B76="LNG carrier", IF(C76<100000,"0-99999", IF(C76<150000,"100000-149999","150000-+")), "CHECK"))))) -> 80000-119999 | F76: =B76&"|"&E76 -> Oil tanker|80000-119999 | G76: =_xlfn.XLOOKUP(F76,Mapping!H:H,Mapping!G:G,"CHECK") -> 28821.516
...

Sheet Mapping
A1: My data vessel type | B1: GreenVoyage type | C1: Why | E1: Green voyage data
A2: chemical | B2: Chemical tanker | C2: Closest direct match for chemical cargo vessels. | E2: Type | F2: Size category | G2: emissions | H2: key
A3: chemoil | B3: Chemical tanker | C3: Hybrid chemical/oil-products vessel; closest to Chemical tanker. | E3: Bulk carrier | F3: 0-9999 | G3: 4689.1838 | H3: =E3&"|"&F3 -> Bulk carrier|0-9999
A4: conro | B4: General cargo | C4: Combination container/ro-ro vessel; no exact GreenVoyage class, closest broad cargo class is General cargo. | E4: Bulk carrier | F4: 10000-34999 | G4: 10987.028 | H4: =E4&"|"&F4 -> Bulk carrier|10000-34999
A5: dry | B5: Bulk carrier | C5: Broad dry cargo category; closest match is Bulk carrier. | E5: Bulk carrier | F5: 35000-59999 | G5: 15035.813 | H5: =E5&"|"&F5 -> Bulk carrier|35000-59999
A6: fso | B6: Oil tanker | C6: Not perfect, but closest available liquid-oil category. | E6: Bulk carrier | F6: 60000-99999 | G6: 21117.137 | H6: =E6&"|"&F6 -> Bulk carrier|60000-99999
A7: liner | B7: General cargo | C7: Liner/container-like service; closest available GreenVoyage class is General cargo. | E7: Bulk carrier | F7: 100000-199999 | G7: 30446.245 | H7: =E7&"|"&F7 -> Bulk carrier|100000-199999
A8: lng | B8: Other liquids tankers | C8: Direct broad match. | E8: Bulk carrier | F8: 200000-+ | G8: 38333.884 | H8: =E8&"|"&F8 -> Bulk carrier|200000-+
A9: lpg | B9: Chemical tanker | C9: Not ideal, but among your listed GreenVoyage options this is the closest liquid/gas-specialized transport class unless you have LPG carrier separately. | E9: Chemical tanker | F9: 0-4999 | G9: 5914.2451 | H9: =E9&"|"&F9 -> Chemical tanker|0-4999
A10: mpp | B10: General cargo | C10: Multi-purpose vessel fits best under General cargo. | E10: Chemical tanker | F10: 5000-9999 | G10: 8000.9025 | H10: =E10&"|"&F10 -> Chemical tanker|5000-9999
A11: obo | B11: Bulk carrier | C11: Ore-bulk-oil vessel is mixed-use; if forced to choose one GreenVoyage class, Bulk carrier is usually the closest operational fit. | E11: Chemical tanker | F11: 10000-19999 | G11: 12170.969 | H11: =E11&"|"&F11 -> Chemical tanker|10000-19999
A12: passenger | B12: General cargo | C12: Weak match, but better to keep separate or exclude; GreenVoyage categories in your sheet do not appear to include passenger. | E12: Chemical tanker | F12: 20000-+ | G12: 20866.017 | H12: =E12&"|"&F12 -> Chemical tanker|20000-+
A13: pctc | B13: General cargo | C13: Pure car/truck carrier is closest to a broad cargo class, though imperfect. | E13: General cargo | F13: 0-4999 | G13: 2148.7943 | H13: =E13&"|"&F13 -> General cargo|0-4999
A14: reefer | B14: General cargo | C14: Refrigerated cargo vessel; closest broad class is General cargo. | E14: General cargo | F14: 5000-9999 | G14: 6161.6698 | H14: =E14&"|"&F14 -> General cargo|5000-9999
... A17: tanker | B17: Oil tanker | C17: Direct broad match. | E17: Oil tanker | F17: 5000-9999 | G17: 7155.0784 | H17: =E17&"|"&F17 -> Oil tanker|5000-9999
E18: Oil tanker | F18: 10000-19999 | G18: 11412.358 | H18: =E18&"|"&F18 -> Oil tanker|10000-19999
E19: Oil tanker | F19: 20000-59999 | G19: 19496.252 | H19: =E19&"|"&F19 -> Oil tanker|20000-59999
E20: Oil tanker | F20: 60000-79999 | G20: 26090.7 | H20: =E20&"|"&F20 -> Oil tanker|60000-79999
E21: Oil tanker | F21: 80000-119999 | G21: 28821.516 | H21: =E21&"|"&F21 -> Oil tanker|80000-119999
E22: Oil tanker | F22: 120000-199999 | G22: 37823.925 | H22: =E22&"|"&F22 -> Oil tanker|120000-199999
E23: Oil tanker | F23: 200000-+ | G23: 62432.826 | H23: =E23&"|"&F23 -> Oil tanker|200000-+
E24: Other liquids tankers | F24: 0-+ | G24: 6663.8331 | H24: =E24&"|"&F24 -> Other liquids tankers|0-+
E25: Refrigerated bulk | F25: 0-1999 | G25: 17516.455 | H25: =E25&"|"&F25 -> Refrigerated bulk|0-1999
E26: Ro-Ro | F26: 0-4999 | G26: 12104.3 | H26: =E26&"|"&F26 -> Ro-Ro|0-4999
E27: Ro-Ro | F27: 5000-+ | G27: 33684.197 | H27: =E27&"|"&F27 -> Ro-Ro|5000-+

Sheet Average emissions to use as rob
A1: Row Labels | B1: Average of CO2 Total (t)
A2: AE SATURN | B2: 934.94927
A3: AFRICAN FLAMINGO | B3: 1397.0221
A4: AFRICAN RAPTOR | B4: 1198.7424
A5: ALORA | B5: 308.20299
A6: AMATERAS HARMONY | B6: 1027.5364
A7: ANTHEMIS | B7: 3066.5278
A8: APIRADEE NAREE | B8: 904.0277
A9: ARSHAM | B9: 869.69603
A10: ARTMAN | B10: 951.77838
A11: Bavand | B11: 1092.6799
A12: BBC EMERALD | B12: 2299.6413
A13: BBC ICELAND | B13: 2020.0292
... A62: Grand Total | B62: 1120.0016

Sheet Emissions
A1: Vessel Name | B1: Vessel Dwt | C1: Intake (t) | D1: Commodity | E1: Leg Type | F1: VLSFO Cons (t) | G1: HSFO Cons (t) | H1: MGO Cons (t) | I1: CO2 Total (t)
A2: AE SATURN | B2: 52385 | E2: ballast | F2: 11.084189 | H2: 0.077361111 | I2: 35.174299
A3: AE SATURN | B3: 52385 | E3: ballast | F3: 419.68619 | H3: 3.1673611 | I3: 1332.5857
A4: AE SATURN | B4: 52385 | E4: ballast | F4: 138.12809 | H4: 1.0405556 | I4: 438.57762
A5: AE SATURN | B5: 52385 | E5: ballast | F5: 289.00005 | H5: 5.2202778 | I5: 927.37538
A6: AE SATURN | B6: 52385 | E6: ballast | F6: 270.27391 | H6: 2.2748611 | I6: 858.92631
A7: AE SATURN | B7: 52385 | E7: ballast | F7: 520.95934 | H7: 3.8819444 | I7: 1653.9884
A8: AE SATURN | B8: 52385 | E8: ballast | F8: 112.37195 | H8: 1.3680556 | I8: 358.47001
A9: AE SATURN | B9: 52385 | E9: ballast | F9: 219.69511 | H9: 1.7131944 | I9: 697.7518
A10: AE SATURN | B10: 52385 | C10: 46405 | E10: laden | F10: 563.828 | H10: 6.5141667 | I10: 1797.5065
A11: AE SATURN | B11: 52385 | C11: 39190 | D11: Clinker | E11: laden | F11: 306.83076 | H11: 4.0659722 | I11: 979.85923
A12: AE SATURN | B12: 52385 | C12: 33640 | D12: Coking Coal | E12: laden | F12: 126.87578 | H12: 2.7359722 | I12: 408.55711
A13: AE SATURN | B13: 52385 | C13: 48625 | D13: Copper Concentrate | E13: laden | F13: 712.85368 | H13: 10.540417 | I13: 2279.9945
A14: AE SATURN | B14: 52385 | C14: 43630 | D14: Di-Amonium Phosphate | E14: laden | F14: 659.47703 | H14: 7.7484722 | I14: 2102.8537
A15: AE SATURN | B15: 52385 | C15: 49180 | D15: Nickel Ore | E15: laden | F15: 166.74724 | H15: 4.765 | I15: 540.69713
A16: AE SATURN | B16: 52385 | C16: 38080 | D16: Steels | E16: laden | F16: 718.95268 | H16: 14.289028 | I16: 2311.2305
A17: AE SATURN | B17: 52385 | C17: 39745 | D17: Steels | E17: laden | F17: 852.5165 | H17: 11.943611 | I17: 2724.5707
A18: GHOUSTA | B18: 50399 | E18: ballast | F18: 1082.1091 | H18: 7.9297222 | I18: 3435.1486
A19: GHOUSTA | B19: 50399 | E19: ballast | F19: 325.07999 | H19: 2.5334722 | I19: 1032.4494
A20: GHOUSTA | B20: 50399 | C20: 47965 | D20: Wheat | E20: laden | F20: 271.47902 | H20: 3.6705556 | I20: 867.19819
A21: GHOUSTA | B21: 50399 | C21: 43127 | D21: Clinker | E21: laden | F21: 255.06975 | H21: 2.9011111 | I21: 813.02574
A22: GHOUSTA | B22: 50399 | C22: 36851 | D22: Gypsum | E22: laden | F22: 246.98401 | H22: 2.6472222 | I22: 786.73362
A23: GHOUSTA | B23: 50399 | E23: ballast | F23: 173.26955 | H23: 1.2570833 | I23: 550.00257
A24: GHOUSTA | B24: 50399 | E24: ballast | F24: 361.71418 | H24: 2.6486111 | I24: 1148.2528
A25: GHOUSTA | B25: 50399 | E25: ballast | F25: 511.38329 | H25: 3.6170833 | I25: 1622.9651
A26: GHOUSTA | B26: 50399 | E26: ballast | F26: 68.403693 | H26: 0.62805556 | I26: 217.55358
A27: GHOUSTA | B27: 50399 | E27: ballast | F27: 215.33812 | H27: 1.8391667 | I27: 684.42677
A28: GHOUSTA | B28: 50399 | E28: ballast | F28: 189.48899 | H28: 1.4419444 | I28: 601.70268
A29: GHOUSTA | B29: 50399 | E29: ballast | F29: 397.325 | H29: 3.4434722 | I29: 1263.0108
A30: GHOUSTA | B30: 50399 | E30: ballast | F30: 141.17113 | H30: 1.1863889 | I30: 448.63378
A31: GHOUSTA | B31: 50399 | E31: ballast | F31: 212.69108 | H31: 1.4666667 | I31: 674.89174
A32: GHOUSTA | B32: 50399 | E32: ballast | F32: 415.46365 | H32: 3.4170833 | I32: 1320.0811
A33: GHOUSTA | B33: 50399 | E33: ballast | F33: 29.087953 | H33: 0.275 | I33: 92.537789
A34: GHOUSTA | B34: 50399 | E34: ballast | F34: 20.727008 | H34: 0.15833333 | I34: 65.81842
... A98: GHOUSTA | B98: 50399 | E98: ballast | F98: 126.0538 | H98: 0.91805556 | I98: 400.13882
A99: GHOUSTA | B99: 50399 | C99: 47965 | E99: laden | F99: 397.18784 | H99: 4.0655556 | I99: 1264.573
A100: GHOUSTA | B100: 50399 | C100: 37897 | E100: laden | F100: 780.70286 | H100: 3.9425694 | I100: 2472.6346
A101: GHOUSTA | B101: 50399 | C101: 34759 | E101: laden | F101: 568.94207 | H101: 7.8058333 | I101: 1817.762
A102: GHOUSTA | B102: 50399 | C102: 38943 | E102: laden | F102: 199.87133 | H102: 2.27375 | I102: 637.08419
A103: GHOUSTA | B103: 50399 | C103: 47965 | D103: Aggregates | E103: laden | F103: 85.456945 | H103: 2.3703472 | I103: 276.87417
...

Sheet Age
A1: IMO | B1: Name | C1: Dwt | D1: Segment | E1: Vessel flag | F1: FINAL AGE
A2: 9221267 | B2: OCEANA KAI | C2: 14804 | D2: chemoil | E2: ABW | F2: 2001
A3: 9155626 | B3: ROYAL A | C3: 18094 | D3: lpg | E3: ABW | F3: 1998
A4: 9007386 | B4: XI WANG MU | C4: 50357 | D4: lpg | E4: ABW | F4: 1991
A5: 9125724 | B5: BLOOMING DALE | C5: 12083 | D5: tanker | E5: ABW | F5: 1996
A6: 9125724 | B6: BLOOMING DALE | C6: 12083 | D6: tanker | E6: ABW | F6: 1996
A7: 9176656 | B7: ASTRID 1 | C7: 32950 | D7: tanker | E7: ABW | F7: 1999
A8: 9277761 | B8: STELLANN | C8: 74999 | D8: tanker | E8: ABW | F8: 2004
A9: 9031519 | B9: MARSER | C9: 49242 | D9: lpg | E9: AGO | F9: 1993
A10: 9031519 | B10: MARSER | C10: 49242 | D10: lpg | E10: AGO | F10: 1993
A11: 9115303 | B11: NAVIXON | C11: 49849 | D11: lpg | E11: AGO | F11: 1996
A12: 9115303 | B12: NAVIXON | C12: 49849 | D12: lpg | E12: AGO | F12: 1996
A13: 9115303 | B13: NAVIXON | C13: 49849 | D13: lpg | E13: AGO | F13: 1996
... A1922: 9454474 | B1922: FIORA | C1922: 4020 | D1922: chemical | E1922: VUT | F1922: 2007

Sheet Shadow fleet
A1: IMO | B1: Vessel Name | C1: Dwt | D1: Vessel SubType | E1: Built | F1: Status
A2: 9247182 | B2: ABIE | C2: 302986 | D2: Crude Oil Tanker | E2: 2002 | F2: GHOST FLEET
A3: 9422964 | B3: ABRAU | C3: 3791 | D3: Bunkering Tanker | E3: 2007 | F3: DARK FLEET
A4: 9247388 | B4: ABROS | C4: 24086 | D4: Chem/Oil Products Tanker | E4: 2004 | F4: SANCTIONED FLEET
A5: 9368223 | B5: ACHILLES | C5: 108953 | D5: Oil Products Tanker | E5: 2008 | F5: SANCTIONED FLEET
A6: 9231767 | B6: ADALYNN | C6: 164551 | D6: Crude Oil Tanker | E6: 2002 | F6: GHOST FLEET
A7: 9234666 | B7: ADELINE G | C7: 317972 | D7: Crude Oil Tanker | E7: 2003 | F7: SANCTIONED FLEET
A8: 9254862 | B8: ADENA | C8: 70146 | D8: Oil Products Tanker | E8: 2003 | F8: SANCTIONED FLEET
A9: 9353125 | B9: ADHARA | C9: 37296 | D9: Chem/Oil Products Tanker | E9: 2008 | F9: SANCTIONED FLEET
A10: 9203784 | B10: ADITYA | C10: 160373 | D10: Crude Oil Tanker | E10: 2000 | F10: SANCTIONED FLEET
A11: 9323314 | B11: ADITYA | C11: 52622 | D11: Chem/Oil Products Tanker | E11: 2006 | F11: SANCTIONED FLEET
A12: 9274446 | B12: ADMIRAL | C12: 159083 | D12: Crude Oil Tanker | E12: 2004 | F12: SANCTIONED FLEET
A13: 9275660 | B13: AEGIS | C13: 69999 | D13: Crude Oil Tanker | E13: 2004 | F13: SANCTIONED FLEET
... A1612: 9908994 | B1612: ZVEZDA DSME 131080 | C1612: 113849 | D1612: Crude Oil Tanker | E1612: 2026 | F1612: SANCTIONED FLEET

Sheet DRY position
A1: Dry Position 1
A2: Prv | B2: Name | C2: Blt | D2: DWT | E2: Position | F2: Zone | G2: Open Dates | H2: Update | I2: Comments (Main) | J2: ETA 1 | K2: ETA M 1 | L2: Freight | M2: NTCE
A3: AXSCLUB | B3: AAL GEELONG | C3: 2009 | D3: 25820 | E3: Antwerp | F3: ARAG | G3: 01 - 07 May 26 | H3: 22 Apr 2026 11:24 GMT+02:00 | I3: 1 | J3: 1
A4: AXSAIS | B4: AFRICAN KESTREL | C4: 2018 | D4: 37787 | E4: Naga (Cebu) | F4: SE ASIA | G4: 28 Apr 26 | H4: 29 Apr 2026 00:42 GMT+02:00 | I4: 1 | J4: 1
A5: AXSAIS | B5: ALVAN | C5: 1998 | D5: 22882 | E5: Bandar Abbas | F5: AG | G5: 24 Apr 26 | H5: 25 Apr 2026 01:52 GMT+02:00 | I5: 1 | J5: 1
A6: AXSAIS | B6: ANASTASIIA | C6: 2006 | D6: 12730 | E6: ARAG | F6: ARAG | G6: 02 May 26 | H6: 02 May 2026 22:02 GMT+02:00 | I6: 1 | J6: 1
A7: AXSAIS | B7: ANNETTE A. DESGAGNES | C7: 2020 | D7: 12325 | E7: Corinto | F7: WCCA | G7: 28 Apr 26 | H7: 28 Apr 2026 10:02 GMT+02:00 | I7: 1 | J7: 1
A8: AXSAIS | B8: APJ KARAN 2 | C8: 2011 | D8: 3000 | E8: Port Blair | F8: EC INDIA | G8: 02 May 26 | H8: 02 May 2026 10:52 GMT+02:00 | I8: 1 | J8: 1
A9: AXSCLUB | B9: ARALIA | C9: 2007 | D9: 12859 | E9: AG | F9: AG | G9: 05 May 26 | H9: 30 Apr 2026 05:16 GMT+02:00 | I9: 1 | J9: 1
B10: ARIES | C10: 1980 | D10: 3574 | I10: 1 | J10: 1
A11: AXSAIS | B11: ARIES | C11: 2020 | D11: 6438 | E11: Guangzhou | F11: FEAST | G11: 28 Apr 26 | H11: 28 Apr 2026 06:32 GMT+02:00 | I11: 1 | J11: 1
A12: AXSAIS | B12: ARIES | C12: 1996 | D12: 5966 | E12: Caucedo | F12: CARIBS | G12: 01 May 26 | H12: 01 May 2026 02:32 GMT+02:00 | I12: 1 | J12: 1
A13: AXSAIS | B13: ASIAN VICTORY | C13: 2003 | D13: 7541 | E13: Kobe | F13: FEAST | G13: 02 May 26 | H13: 02 May 2026 02:32 GMT+02:00 | I13: 1 | J13: 1
B14: AURA | C14: 1993 | D14: 3645 | I14: 1 | J14: 1
A15: AXSAIS | B15: AYSAN | C15: 1998 | D15: 22882 | E15: Bandar Abbas | F15: AG | G15: 10 Apr 26 | H15: 10 Apr 2026 15:32 GMT+02:00 | I15: 1 | J15: 1
A16: AXSAIS | B16: BAK 8 | C16: 1996 | D16: 2326 | E16: Port Rashid | F16: AG | G16: 31 Mar 26 | H16: 31 Mar 2026 05:32 GMT+02:00 | I16: 1 | J16: 1
A17: AXSAIS | B17: BASRAH | C17: 2014 | D17: 17806 | E17: Jebel Ali | F17: AG | G17: 03 May 26 | H17: 03 May 2026 09:12 GMT+02:00 | I17: 1 | J17: 1
A18: AXSAIS | B18: BBC EMERALD | C18: 2013 | D18: 14371 | E18: NW AFRICA | F18: NW AFRICA | G18: 30 Apr 26 | H18: 30 Apr 2026 08:52 GMT+02:00 | I18: 1 | J18: 1
A19: AXSCLUB | B19: BBC GANGES | C19: 2010 | D19: 16943 | E19: AG | F19: AG | G19: 07 Mar 26 | H19: 19 Feb 2026 09:38 GMT+01:00 | I19: 1 | J19: 1
A20: AXSCLUB | B20: BBC HELSINKI | C20: 2025 | D20: 12266 | E20: China North | F20: FEAST | G20: 10 Mar 26 | H20: 02 Mar 2026 11:32 GMT+01:00 | I20: 1 | J20: 1
A21: AXSCLUB | B21: BBC ICELAND | C21: 2013 | D21: 24935 | E21: China North | F21: FEAST | G21: 10 May 26 | H21: 30 Apr 2026 05:16 GMT+02:00 | I21: 1 | J21: 1
