Workbook

Sheet Export
A1: Date | B1: Move | C1: IMO | D1: Name | E1: Shadow | F1: Shadow Status | G1: Dwt | H1: Segment | I1: Vessel flag | J1: ais destination
A2: 46099 | B2: East→West | C2: 8912546 | D2: SALUTE | E2: =IF(COUNTIF(Sheet1!A:A,Export!C2)>0,1,0) -> 0 | F2: =IF(COUNTIF(Sheet1!B:B,Export!D2)>0,Sheet1!F2,0) -> 0 | G2: 49301 | H2: lpg | I2: BWA | J2: For Orders
A3: 46099 | B3: East→West | C3: 9100504 | D3: GULF KING | E3: =IF(COUNTIF(Sheet1!A:A,Export!C3)>0,1,0) -> 0 | F3: =IF(COUNTIF(Sheet1!B:B,Export!D3)>0,Sheet1!F3,0) -> 0 | G3: 8637 | H3: mpp | I3: COM
A4: 46099 | B4: East→West | C4: 9309239 | D4: EURO VIKING | E4: =IF(COUNTIF(Sheet1!A:A,Export!C4)>0,1,0) -> 1 | F4: =IF(COUNTIF(Sheet1!B:B,Export!D4)>0,Sheet1!F4,0) -> SANCTIONED FLEET | G4: 24333 | H4: chemoil | I4: CUW
A5: 46099 | B5: West→East | C5: 9307009 | D5: YES | E5: =IF(COUNTIF(Sheet1!A:A,Export!C5)>0,1,0) -> 0 | F5: =IF(COUNTIF(Sheet1!B:B,Export!D5)>0,Sheet1!F5,0) -> 0 | G5: 66940 | H5: liner | I5: GUY | J5: Jebel Ali
A6: 46098 | B6: East→West | C6: 9125724 | D6: BLOOMING DALE | E6: =IF(COUNTIF(Sheet1!A:A,Export!C6)>0,1,0) -> 1 | F6: =IF(COUNTIF(Sheet1!B:B,Export!D6)>0,Sheet1!F6,0) -> GHOST FLEET | G6: 12083 | H6: tanker | I6: ABW | J6: Khor Fakkan
A7: 46098 | B7: East→West | C7: 9211664 | D7: CHEMTRANS | E7: =IF(COUNTIF(Sheet1!A:A,Export!C7)>0,1,0) -> 0 | F7: =IF(COUNTIF(Sheet1!B:B,Export!D7)>0,Sheet1!F7,0) -> 0 | G7: 6712 | H7: chemical | I7: PLW | J7: Hamriya Free Zone Port
A8: 46098 | B8: East→West | C8: 9287962 | D8: JC PEACE | E8: =IF(COUNTIF(Sheet1!A:A,Export!C8)>0,1,0) -> 0 | F8: =IF(COUNTIF(Sheet1!B:B,Export!D8)>0,Sheet1!F8,0) -> 0 | G8: 53299 | H8: dry | I8: PAN | J8: Umm Qasr
A9: 46098 | B9: East→West | C9: 9307009 | D9: YES | E9: =IF(COUNTIF(Sheet1!A:A,Export!C9)>0,1,0) -> 0 | F9: =IF(COUNTIF(Sheet1!B:B,Export!D9)>0,Sheet1!F9,0) -> 0 | G9: 66940 | H9: liner | I9: GUY | J9: Jebel Ali
A10: 46098 | B10: East→West | C10: 9574016 | D10: AL SADR - I | E10: =IF(COUNTIF(Sheet1!A:A,Export!C10)>0,1,0) -> 0 | F10: =IF(COUNTIF(Sheet1!B:B,Export!D10)>0,Sheet1!F10,0) -> 0 | G10: 13944 | H10: liner | I10: ARE | J10: World Wide
A11: 46098 | B11: East→West | C11: 9700017 | D11: HATTHAYA NAREE | E11: =IF(COUNTIF(Sheet1!A:A,Export!C11)>0,1,0) -> 0 | F11: =IF(COUNTIF(Sheet1!B:B,Export!D11)>0,Sheet1!F11,0) -> 0 | G11: 39266 | H11: dry | I11: SGP | J11: For Orders
A12: 46098 | B12: West→East | C12: 9088536 | D12: SEA BIRD | E12: =IF(COUNTIF(Sheet1!A:A,Export!C12)>0,1,0) -> 0 | F12: =IF(COUNTIF(Sheet1!B:B,Export!D12)>0,Sheet1!F12,0) -> 0 | G12: 49679 | H12: lpg | I12: PLW | J12: Hamriya Free Zone Port
A13: 46098 | B13: West→East | C13: 9277761 | D13: STELLANN | E13: =IF(COUNTIF(Sheet1!A:A,Export!C13)>0,1,0) -> 1 | F13: =IF(COUNTIF(Sheet1!B:B,Export!D13)>0,Sheet1!F13,0) -> SANCTIONED FLEET | G13: 74999 | H13: tanker | I13: ABW | J13: Lianyungang
A14: 46098 | B14: West→East | C14: 9283007 | D14: ARTABAZ | E14: =IF(COUNTIF(Sheet1!A:A,Export!C14)>0,1,0) -> 0 | F14: =IF(COUNTIF(Sheet1!B:B,Export!D14)>0,Sheet1!F14,0) -> 0 | G14: 33853 | H14: liner | I14: IRN | J14: Port Kelang
A15: 46098 | B15: West→East | C15: 9284154 | D15: ARTAM | E15: =IF(COUNTIF(Sheet1!A:A,Export!C15)>0,1,0) -> 0 | F15: =IF(COUNTIF(Sheet1!B:B,Export!D15)>0,Sheet1!F15,0) -> 0 | G15: 37875 | H15: liner | I15: IRN | J15: Chabahar
A16: 46097 | B16: East→West | C16: 9056806 | D16: VISTA III | E16: =IF(COUNTIF(Sheet1!A:A,Export!C16)>0,1,0) -> 0 | F16: =IF(COUNTIF(Sheet1!B:B,Export!D16)>0,Sheet1!F16,0) -> 0 | G16: 142674 | H16: fso | I16: PAN | J16: Fujairah
A17: 46097 | B17: East→West | C17: 9115303 | D17: NAVIXON | E17: =IF(COUNTIF(Sheet1!A:A,Export!C17)>0,1,0) -> 0 | F17: =IF(COUNTIF(Sheet1!B:B,Export!D17)>0,Sheet1!F17,0) -> 0 | G17: 49849 | H17: lpg | I17: AGO | J17: For Orders
A18: 46097 | B18: East→West | C18: 9117600 | D18: OCEAN LION | E18: =IF(COUNTIF(Sheet1!A:A,Export!C18)>0,1,0) -> 0 | F18: =IF(COUNTIF(Sheet1!B:B,Export!D18)>0,Sheet1!F18,0) -> 0 | G18: 29538 | H18: mpp | I18: COM
A19: 46097 | B19: East→West | C19: 9141962 | D19: GAS RGA | E19: =IF(COUNTIF(Sheet1!A:A,Export!C19)>0,1,0) -> 0 | F19: =IF(COUNTIF(Sheet1!B:B,Export!D19)>0,Sheet1!F19,0) -> 0 | G19: 4252 | H19: lpg | I19: PLW | J19: Khor Fakkan
A20: 46097 | B20: East→West | C20: 9220938 | D20: MODESTE | E20: =IF(COUNTIF(Sheet1!A:A,Export!C20)>0,1,0) -> 1 | F20: =IF(COUNTIF(Sheet1!B:B,Export!D20)>0,Sheet1!F20,0) -> SANCTIONED FLEET | G20: 42721 | H20: chemoil | I20: GMB | J20: Shinas
A21: 46097 | B21: East→West | C21: 9232369 | D21: NYMPH THETIS | E21: =IF(COUNTIF(Sheet1!A:A,Export!C21)>0,1,0) -> 1 | F21: =IF(COUNTIF(Sheet1!B:B,Export!D21)>0,Sheet1!F21,0) -> SANCTIONED FLEET | G21: 17427 | H21: chemical | I21: BRB
A22: 46097 | B22: East→West | C22: 9237395 | D22: NAVIS | E22: =IF(COUNTIF(Sheet1!A:A,Export!C22)>0,1,0) -> 0 | F22: =IF(COUNTIF(Sheet1!B:B,Export!D22)>0,Sheet1!F22,0) -> 0 | G22: 28379 | H22: dry | I22: KNA | J22: Khor Fakkan
A23: 46097 | B23: East→West | C23: 9256925 | D23: TARYN EVE | E23: =IF(COUNTIF(Sheet1!A:A,Export!C23)>0,1,0) -> 0 | F23: =IF(COUNTIF(Sheet1!B:B,Export!D23)>0,Sheet1!F23,0) -> 0 | G23: 47791 | H23: chemoil | I23: BRB | J23: Khor Fakkan
A24: 46097 | B24: East→West | C24: 9267962 | D24: HOOT | E24: =IF(COUNTIF(Sheet1!A:A,Export!C24)>0,1,0) -> 0 | F24: =IF(COUNTIF(Sheet1!B:B,Export!D24)>0,Sheet1!F24,0) -> 0 | G24: 8709 | H24: lpg | I24: BWA | J24: Khor Fakkan
A25: 46097 | B25: East→West | C25: 9292046 | D25: NOVA CREST | E25: =IF(COUNTIF(Sheet1!A:A,Export!C25)>0,1,0) -> 1 | F25: =IF(COUNTIF(Sheet1!B:B,Export!D25)>0,Sheet1!F25,0) -> SANCTIONED FLEET | G25: 46697 | H25: tanker | I25: BRB | J25: Khor Fakkan
A26: 46097 | B26: East→West | C26: 9322097 | D26: AVIDEEP | E26: =IF(COUNTIF(Sheet1!A:A,Export!C26)>0,1,0) -> 0 | F26: =IF(COUNTIF(Sheet1!B:B,Export!D26)>0,Sheet1!F26,0) -> 0 | G26: 13125 | H26: chemoil | I26: PAN | J26: Khor Fakkan
A27: 46097 | B27: East→West | C27: 9350290 | D27: BW LOYALTY | E27: =IF(COUNTIF(Sheet1!A:A,Export!C27)>0,1,0) -> 0 | F27: =IF(COUNTIF(Sheet1!B:B,Export!D27)>0,Sheet1!F27,0) -> 0 | G27: 55057 | H27: lpg | I27: IND | J27: Port Rashid
A28: 46097 | B28: East→West | C28: 9389863 | D28: SHAHRAZAD | E28: =IF(COUNTIF(Sheet1!A:A,Export!C28)>0,1,0) -> 0 | F28: =IF(COUNTIF(Sheet1!B:B,Export!D28)>0,Sheet1!F28,0) -> 0 | G28: 74999 | H28: tanker | I28: LBR | J28: For Orders
A29: 46097 | B29: East→West | C29: 9451305 | D29: DA ZI YUN | E29: =IF(COUNTIF(Sheet1!A:A,Export!C29)>0,1,0) -> 0 | F29: =IF(COUNTIF(Sheet1!B:B,Export!D29)>0,Sheet1!F29,0) -> 0 | G29: 28451 | H29: mpp | I29: HKG | J29: World Wide
A30: 46097 | B30: East→West | C30: 9470076 | D30: STAR FLAME | E30: =IF(COUNTIF(Sheet1!A:A,Export!C30)>0,1,0) -> 0 | F30: =IF(COUNTIF(Sheet1!B:B,Export!D30)>0,Sheet1!F30,0) -> 0 | G30: 80448 | H30: dry | I30: CYM | J30: Fujairah
A31: 46097 | B31: East→West | C31: 9513763 | D31: NAVE SYNERGY | E31: =IF(COUNTIF(Sheet1!A:A,Export!C31)>0,1,0) -> 0 | F31: =IF(COUNTIF(Sheet1!B:B,Export!D31)>0,Sheet1!F31,0) -> 0 | G31: 309483 | H31: tanker | I31: LBR | J31: Fujairah
A32: 46097 | B32: East→West | C32: 9516545 | D32: DAISY | E32: =IF(COUNTIF(Sheet1!A:A,Export!C32)>0,1,0) -> 0 | F32: =IF(COUNTIF(Sheet1!B:B,Export!D32)>0,Sheet1!F32,0) -> 0 | G32: 7281 | H32: tanker | I32: DMA | J32: Fujairah
A33: 46097 | B33: East→West | C33: 9534793 | D33: AL SALMI | E33: =IF(COUNTIF(Sheet1!A:A,Export!C33)>0,1,0) -> 0 | F33: =IF(COUNTIF(Sheet1!B:B,Export!D33)>0,Sheet1!F33,0) -> GHOST FLEET | G33: 319660 | H33: tanker | I33: KWT | J33: Qingdao
... A60: 46096 | B60: West→East | C60: 9115303 | D60: NAVIXON | E60: =IF(COUNTIF(Sheet1!A:A,Export!C60)>0,1,0) -> 0 | F60: =IF(COUNTIF(Sheet1!B:B,Export!D60)>0,Sheet1!F60,0) -> 0 | G60: 49849 | H60: lpg | I60: AGO | J60: For Orders
A61: 46096 | B61: West→East | C61: 9232369 | D61: NYMPH THETIS | E61: =IF(COUNTIF(Sheet1!A:A,Export!C61)>0,1,0) -> 1 | F61: =IF(COUNTIF(Sheet1!B:B,Export!D61)>0,Sheet1!F61,0) -> SANCTIONED FLEET | G61: 17427 | H61: chemical | I61: BRB
A62: 46096 | B62: West→East | C62: 9267948 | D62: OCEAN GUARDIAN | E62: =IF(COUNTIF(Sheet1!A:A,Export!C62)>0,1,0) -> 1 | F62: =IF(COUNTIF(Sheet1!B:B,Export!D62)>0,Sheet1!F62,0) -> SANCTIONED FLEET | G62: 46101 | H62: tanker | I62: PAN | J62: For Orders
A63: 46096 | B63: West→East | C63: 9301031 | D63: STAR GWYNETH | E63: =IF(COUNTIF(Sheet1!A:A,Export!C63)>0,1,0) -> 0 | F63: =IF(COUNTIF(Sheet1!B:B,Export!D63)>0,Sheet1!F63,0) -> 0 | G63: 82790 | H63: dry | I63: MHL | J63: Santos
A64: 46096 | B64: West→East | C64: 9307009 | D64: YES | E64: =IF(COUNTIF(Sheet1!A:A,Export!C64)>0,1,0) -> 0 | F64: =IF(COUNTIF(Sheet1!B:B,Export!D64)>0,Sheet1!F64,0) -> 0 | G64: 66940 | H64: liner | I64: GUY | J64: Jebel Ali
A65: 46096 | B65: West→East | C65: 9350290 | D65: BW LOYALTY | E65: =IF(COUNTIF(Sheet1!A:A,Export!C65)>0,1,0) -> 0 | F65: =IF(COUNTIF(Sheet1!B:B,Export!D65)>0,Sheet1!F65,0) -> 0 | G65: 55057 | H65: lpg | I65: IND | J65: Port Rashid
A66: 46096 | B66: West→East | C66: 9389863 | D66: SHAHRAZAD | E66: =IF(COUNTIF(Sheet1!A:A,Export!C66)>0,1,0) -> 0 | F66: =IF(COUNTIF(Sheet1!B:B,Export!D66)>0,Sheet1!F66,0) -> 0 | G66: 74999 | H66: tanker | I66: LBR | J66: For Orders
...

Sheet Sheet1
A1: IMO | B1: Vessel Name | C1: Dwt | D1: Vessel SubType | E1: Built | F1: Status
A2: 9247182 | B2: ABIE | C2: 302986 | D2: Crude Oil Tanker | E2: 2002 | F2: GHOST FLEET
A3: 9422964 | B3: ABRAU | C3: 3791 | D3: Bunkering Tanker | E3: 2007 | F3: DARK FLEET
A4: 9247388 | B4: ABROS | C4: 24086 | D4: Chem/Oil Products Tanker | E4: 2004 | F4: SANCTIONED FLEET
A5: 9368223 | B5: ACHILLES | C5: 108953 | D5: Oil Products Tanker | E5: 2008 | F5: SANCTIONED FLEET
A6: 9231767 | B6: ADALYNN | C6: 164551 | D6: Crude Oil Tanker | E6: 2002 | F6: GHOST FLEET
A7: 9234666 | B7: ADELINE G | C7: 317972 | D7: Crude Oil Tanker | E7: 2003 | F7: SANCTIONED FLEET
A8: 9254862 | B8: ADENA | C8: 70146 | D8: Oil Products Tanker | E8: 2003 | F8: SANCTIONED FLEET
A9: 9353125 | B9: ADHARA | C9: 37296 | D9: Chem/Oil Products Tanker | E9: 2008 | F9: SANCTIONED FLEET
A10: 9203784 | B10: ADITYA | C10: 160373 | D10: Crude Oil Tanker | E10: 2000 | F10: SANCTIONED FLEET
A11: 9323314 | B11: ADITYA | C11: 52622 | D11: Chem/Oil Products Tanker | E11: 2006 | F11: SANCTIONED FLEET
A12: 9274446 | B12: ADMIRAL | C12: 159083 | D12: Crude Oil Tanker | E12: 2004 | F12: SANCTIONED FLEET
A13: 9275660 | B13: AEGIS | C13: 69999 | D13: Crude Oil Tanker | E13: 2004 | F13: SANCTIONED FLEET
... A1612: 9908994 | B1612: ZVEZDA DSME 131080 | C1612: 113849 | D1612: Crude Oil Tanker | E1612: 2026 | F1612: SANCTIONED FLEET
